Workbook

Sheet 00-使用说明
A1: OpenWebUI L1 知识库基础测试标准v1.1
A3: 适用范围：OpenWebUI 自定义模型 + Base Model + Knowledge。L1 阶段不启用 Skills / Tools，重点验证知识库本身。
A5: 测试步骤 | B5: 检查对象 | C5: 测试人员要回答的问题 | D5: 通过标准 | E5: 常见归因 | F5: 是否必测 | G5: 建议记录 | H5: 备注
A6: 1 | B6: 原始文档 | C6: 原始文档里是否有明确答案？ | D6: 能明确找到标准答案，或明确确认无答案 | E6: P1 | F6: 是 | G6: 标准来源/页码/章节 | H6: 所有 Case 的起点
A7: 2 | B7: 文档解析 | C7: 上传入库后，文字/表格/结构是否完整？ | D7: 正文完整，结构无明显错乱，关键内容可检索 | E7: P2 | F7: 是 | G7: 解析结果摘要 | H7: 复杂 PDF/Excel/图片重点
A8: 3 | B8: 检索/召回 | C8: 如界面能观察，判断是否找到正确知识；如看不到 Top K/Chunk，只记录最终回答、引用和“异常现象”，不要强行做技术归因。 | D8: 正确内容进入检索结果 | E8: P3/P4 | F8: 是 | G8: 实际引用/检索内容 | H8: P1~P10 最终归因由负责人/研发复核
A9: 4 | B9: 最终回答 | C9: 找到正确内容后，答案是否正确完整？ | D9: 核心事实正确，无关键遗漏 | E9: P5 | F9: 是 | G9: 实际回答
A10: 5 | B10: 引用 | C10: 引用是否真正支持答案？ | D10: 来源正确且能核对到原文 | E10: P6 | F10: 是 | G10: 引用文件/位置
A11: 6 | B11: 无答案/幻觉 | C11: 知识库没答案时是否乱编？ | D11: 应明确说明无法从当前知识库得到结论 | E11: P7 | F11: 是 | G11: 无答案测试结果 | H11: 企业知识库重点
A12: 7 | B12: 多轮/权限 | C12: 连续追问和权限隔离是否正常？ | D12: 上下文一致；未授权内容不可见 | E12: P8/P9 | F12: 专项 | G12: 用户/角色/会话信息 | H12: 权限泄露为红线
A14: 测试人员重点做“事实观察与评分”；P1~P10 根因和 S0~S3 最终定级由测试负责人/研发复核。看不到 Top K、Chunk、解析文本时，不要求测试人员猜技术原因。
A15: 建议：测试人员只需先掌握“原文有没有 → 解析对不对 → 找没找到 → 答没答对 → 引用对不对 → 没答案会不会编”这条主线。
A17: 批次字段与 Case 字段的填写规则
A18: 字段层级 | B18: 放在哪个 Sheet | C18: 谁填写 | D18: 是否允许每条 Case 不同 | E18: 说明 | F18: 示例 | G18: 避免的问题 | H18: 备注
A19: 批次级 | B19: 90-测试批次配置 | C19: 批次负责人 | D19: 否 | E19: 同一个 Run ID 下保持一致 | F19: Base Model、Knowledge、Embedding、Top K、OpenWebUI版本 | G19: 避免每条 Case 重复填写和配置漂移
A20: 责任级 | B20: 90-测试批次配置 | C20: 批次负责人 | D20: 否 | E20: 负责组织本批次，不等于每条 Case 的实际执行人 | F20: 批次负责人=测试人员A | G20: 避免和执行人混淆
A21: 执行级 | B21: 91/92 | C21: 执行测试人员 | D21: 是 | E21: 同一 Run ID 可由多人分工执行 | F21: Case001=A，Case002=B | G21: 支持多人协作和工作量统计 | H21: 保留
A22: 执行时间 | B22: 91/92 | C22: 执行测试人员 | D22: 是 | E22: 记录每条 Case 实际执行日期 | F22: 2026-08-19 | G22: 与90的批次日期区分 | H22: 保留
A23: 知识库 | B23: 91/92 | C23: 同 90-测试批次配置 | D23: 否 | E23: 通过 Run ID 从90自动带出，不手填 | F23: RUN-L1-001 → 行政制度知识库 | G23: 避免 Run ID 与知识库不一致 | H23: 前200行已自动关联
A24: 复核级 | B24: 91 | C24: 测试负责人/研发 | D24: 是 | E24: 失败归因（负责人）、严重级别（负责人）由复核人员填写 | F24: 异常现象=疑似未找到知识 → 负责人结合证据判断 P3/P4 | G24: 避免非技术测试人员误归因 | H24: 测试人员无需填写技术归因
A26: 字段顺序原则：标识/责任 → 测试环境或文档输入 → 问题/预期 → 实际结果 → 评分 → 最终结果/归因 → 备注。
A28: OpenWebUI 对话链接记录规则
A29: 字段 | B29: 普通通过Case | C29: 失败/需回归Case | D29: 多轮问答 | E29: 权限测试 | F29: 用途 | G29: 注意事项 | H29: 备注
A30: OpenWebUI对话链接 | B30: 建议填写 | C30: 必须填写 | D30: 必须填写 | E30: 必须填写 | F30: 便于研发复现完整上下文、引用与多轮交互 | G30: 链接可能因环境清理失效；S0/S1问题仍应在备注中保留关键证据，必要时截图 | H30: 92-文档解析Case无需记录
A32: 正式测试数据填写约定
A33: 项目 | B33: 约定 | C33: 原因 | D33: 91 | E33: 92 | F33: 90 | G33: 建议 | H33: 备注
A34: 示例数据 | B34: EX- 开头的 Case/Parse Case 仅用于示范，不计入正式统计 | C34: 避免示例污染测试结果 | D34: 适用 | E34: 适用 | F34: — | G34: 正式执行前可保留用于参考，但统计时过滤 EX-*
A35: 正式Case ID | B35: 建议使用 L1-0001、L1-0002…；解析使用 PARSE-0001… | C35: 便于唯一识别与回归 | D35: L1-* | E35: PARSE-* | F35: — | G35: 不要重复使用 ID
A36: Run ID | B36: 配置发生变化时新建 Run ID，不修改历史批次含义 | C36: 保证结果可复现 | D36: 引用 | E36: 引用 | F36: 主维护 | G36: 模型/Prompt/Knowledge/Embedding/TopK 任一关键配置变化都建议新建 Run
A38: 测试人员速查卡
A39: 场景 | B39: 原文 | C39: 找到正确内容 | D39: 评分建议 | E39: 异常现象 | F39: 最终结果 | G39: 负责人后续 | H39: 注意
A40: 正常通过 | B40: 是 | C40: 是 | D40: 通常 5/5/5；轻微非关键偏差按05评分 | E40: 无明显异常 | F40: 通过 | G40: 无需归因 | H40: 通过 Case 对话链接建议填写
A41: 无答案正确拒答 | B41: 否 | C41: 无法判断 | D41: 正确性/完整性按拒答质量；引用可 N/A | E41: 无明显异常 | F41: 通过 | G41: 无需归因 | H41: 确认原文真的无答案
A42: 明显幻觉 | B42: 否 | C42: 否/无法判断 | D42: 按实际回答评分；不要机械固定分值 | E42: 疑似幻觉 | F42: 失败 | G42: 负责人确认 P7 / S1 | H42: 对话链接必填
A43: 疑似未召回 | B43: 是 | C43: 否 | D43: 回答分数按实际回答；即使碰巧答对，RAG Case 仍失败 | E43: 疑似未找到知识 | F43: 失败 | G43: 负责人区分 P3/P4/其他 | H43: 不要由测试人员猜 Embedding/Chunk
A44: 引用错误 | B44: 是 | C44: 是/部分 | D44: 回答可高分，但引用准确性按05扣分 | E44: 引用错误 | F44: 失败或需回归 | G44: 负责人确认 P6 与严重级别 | H44: 旧版本引用属于错误
A46: 92 执行提示：只有在测试人员能查看解析后的正文、表格/OCR、顺序或 Metadata 时，才要求其打对应解析分；若 OpenWebUI UI 无法观察这些内容，92 应由技术测试人员/负责人执行。

Sheet 01-测试题来源指南
A1: 测试题目与测试文档从哪里来
A3: 原则：优先使用企业内部非公开、可授权用于测试的资料。这样可以减少“基础模型本来就知道答案”的干扰，更能测试 Knowledge 是否真正生效。
A5: 推荐来源 | B5: 典型文档 | C5: 为什么适合 | D5: 推荐题型 | E5: 隐私/安全要求 | F5: 优先级 | G5: 是否适合公开模型 | H5: 备注
A6: 行政制度 | B6: 办公制度、会议室规则、差旅制度、资产领用、访客管理 | C6: 事实清晰、结构稳定、内部特有 | D6: 事实、步骤、条件判断、版本冲突 | E6: 避免真实员工个人信息 | F6: 高 | G6: 适合 | H6: 非常适合首批 Golden Case
A7: HR 制度 | B7: 入职流程、请假制度、绩效流程、培训制度、员工手册 | C7: 内部规则明确，公开模型无法准确知道企业内部细节 | D7: 事实、流程、拒答、跨文档 | E7: 使用制度文本；不要使用真实薪资、身份证、健康等个人敏感数据 | F7: 高 | G7: 适合 | H7: 优先使用制度，不用人员档案
A8: IT/运维 SOP | B8: 账号申请、VPN、设备接入、故障处理、变更流程、值班规范 | C8: 和企业实际场景高度一致 | D8: 步骤、参数、异常、跨段推理 | E8: 脱敏主机名/IP/密钥/账号 | F8: 高 | G8: 适合 | H8: 技术知识库重点
A9: 安全与合规制度 | B9: 密码规范、数据分级、权限申请、审计规范 | C9: 非常适合权限、拒答、引用测试 | D9: 事实、权限、条件判断 | E9: 不得放真实密钥、漏洞细节、敏感审计数据 | F9: 高 | G9: 适合
A10: 采购/财务流程 | B10: 报销流程、采购审批、费用标准、预算申请 | C10: 规则多、容易做复杂 Case | D10: 流程、条件、表格、跨文档 | E10: 使用制度/标准，不使用真实个人银行/薪资数据 | F10: 中 | G10: 适合
A11: 产品/项目内部文档 | B11: 内部产品说明、项目 SOP、版本说明、FAQ | C11: 私有知识明显，容易验证 Knowledge 增益 | D11: 事实、总结、版本冲突 | E11: 按内部权限要求使用 | F11: 高 | G11: 适合
A12: 内部培训材料 | B12: 新人培训、部门培训、操作手册 | C12: 结构多样，适合多格式测试 | D12: 事实、步骤、总结 | E12: 去除个人信息 | F12: 中 | G12: 适合
A13: 会议纪要/决策记录 | B13: 经过脱敏的项目决策、规则变更记录 | C13: 适合版本、新旧冲突、时间语义 | D13: 版本冲突、跨文档 | E13: 必须脱敏且确认可用于测试 | F13: 中 | G13: 谨慎 | H13: 优先使用模拟纪要
A14: 合成企业私有资料 | B14: 人工编写一套虚构公司制度/项目资料 | C14: 完全可控、无泄密风险、标准答案明确 | D14: 所有题型 | E14: 无真实敏感数据 | F14: 高 | G14: 非常适合 | H14: 推荐用于第一批标准化基准集
A15: 公开资料 | B15: 公开产品手册、百科、公开博客 | C15: 基础模型可能已经知道答案，难判断 Knowledge 是否生效 | D15: 仅用于解析/格式测试 | E15: 无额外要求 | F15: 低 | G15: 不优先 | H15: 不要作为主要问答评测来源
A17: 推荐组合：50% 企业内部制度/SOP + 30% 合成企业私有资料 + 20% 内部产品/项目资料。公开资料尽量只用于文档解析格式验证。
A19: Golden Dataset 题型 | B19: 示例 | C19: 测试目标 | D19: 最低数量 | E19: 推荐数量 | F19: 是否固定复用 | G19: 执行要求 | H19: 备注
A20: 直接事实题 | B20: 差旅住宿标准是多少？ | C20: 精准事实检索 | D20: ≥10 | E20: 10~15 | F20: 是 | G20: 关键数值/条件必须有明确标准答案 | H20: 避免只复制原文整句
A21: 同义改写题 | B21: 出差住酒店最高能报多少？ | C21: 语义召回 | D21: ≥6 | E21: 6~10 | F21: 是 | G21: 问题措辞与文档原词有明显差异 | H21: 验证语义召回
A22: 流程/步骤题 | B22: 新员工如何申请 VPN？ | C22: 步骤完整性 | D22: ≥6 | E22: 6~10 | F22: 是 | G22: 标准答案预先列出必答步骤 | H22: 便于完整性评分
A23: 跨段/跨文档题 | B23: 请假超过3天需要哪些审批？ | C23: 多 Chunk/多文档整合 | D23: ≥4 | E23: 4~8 | F23: 是 | G23: 答案至少依赖两个段落或来源
A24: 无答案题 | B24: 公司明年会不会涨薪？ | C24: 拒答/幻觉 | D24: ≥3 | E24: 3~5 | F24: 是 | G24: 必须先确认知识库确实无明确答案 | H24: 避免争议问题
A25: 版本冲突题 | B25: 当前最新差旅标准是什么？ | C25: 新旧版本判断 | D25: ≥2 | E25: 2~4 | F25: 是 | G25: 文档必须存在明确版本/生效信息
A26: 多轮/权限专项 | B26: “那超过7天呢？” / 权限隔离 | C26: 上下文与权限 | D26: ≥3多轮；≥2权限 | E26: 按需要 | F26: 是 | G26: 专项执行；权限泄露为红线 | H26: 可与其他题型交叉
A28: Golden Dataset 固定复用规则：先建立约 30~50 个稳定 Case；同一批 Case 在不同 Run ID 下重复执行。模型、Prompt、Knowledge、Embedding、Top K 等关键配置变化时新建 Run ID，但不要随 Run 更换题目，否则不同 Run 无法公平比较。

Sheet 02-RAG术语与归因
A1: RAG 常见术语与失败归因参考
A3: 链路：用户问题 → 文档解析 → Chunk → Embedding → 检索/召回 → Reranker → Top K → LLM → 引用。
A5: 术语 | B5: 英文 | C5: 是什么意思 | D5: 示例 | E5: 测试时看什么 | F5: 常见问题 | G5: 处理方向 | H5: 测试人员要点
A6: 召回 | B6: Retrieval / Recall | C6: 从知识库中找相关文档或 Chunk | D6: 问内部差旅标准，Top5 应出现正确制度片段 | E6: 正确内容是否进入 Top K | F6: 正确文档没找到 | G6: Embedding/检索/Top K | H6: 先判断“找没找到”
A7: Recall@K | B7: Recall@K | C7: 正确 Chunk 是否进入前 K 个结果 | D7: 100题中94题在Top5命中，Recall@5=94% | E7: Recall@5/10 | F7: 低 Recall 导致模型没有证据 | G7: 检索策略 | H7: 一般由研发统计
A8: Chunk | B8: Chunking | C8: 长文档切成用于检索的小片段 | D8: 审批条件和审批人不应被不合理拆开 | E8: 语义是否被切断 | F8: 标题/表格/代码被拆散 | G8: Chunk size/overlap | H8: 文档对但片段不完整时考虑
A9: Embedding | B9: Embedding | C9: 将文本转成向量做语义匹配 | D9: “酒店最高能报多少”应匹配“住宿报销上限” | E9: 同义表达能否搜到 | F9: 词不一样就漏召回 | G9: Embedding模型 | H9: 不需要理解算法
A10: Reranker | B10: Reranker | C10: 对召回结果二次排序 | D10: Top20重排成Top5 | E10: 正确片段是否被排到前面 | F10: 正确结果被排掉 | G10: 重排模型/阈值 | H10: 研发重点
A11: 引用 | B11: Citation | C11: 答案对应的原始来源 | D11: 回答住宿标准并引用正确制度章节 | E11: 来源是否真支持结论 | F11: 答对但引错 | G11: Prompt/引用链路 | H11: 要点开核对
A12: 幻觉 | B12: Hallucination | C12: 没有证据却给出确定答案 | D12: 没有涨薪计划资料却回答“明年涨10%” | E12: 知识库是否有证据 | F12: 看似合理但无来源 | G12: 拒答策略 | H12: 重点统计
A13: 拒答 | B13: No-answer | C13: 证据不足时明确无法回答 | D13: “当前知识库没有足够信息判断” | E13: 无答案题是否正确拒答 | F13: 强行猜答案 | G13: Prompt/阈值 | H13: 拒答不等于失败
A14: 归因 | B14: Root Cause Attribution | C14: 给失败 Case 判断根因 | D14: 召回错、Chunk错、生成错要区分 | E14: 错误发生在哪一层 | F14: 只写“回答不好” | G14: P1~P10 | H14: 测试人员记录异常现象；负责人完成 P1~P10 归因
A16: 编码 | B16: 归因 | C16: 典型现象 | D16: 示例 | E16: 如何判断 | F16: 技术侧重点 | G16: 常见严重级别（参考） | H16: 备注
A17: P1 | B17: 文档缺失 | C17: 原文没有答案 | D17: 制度里没有明年涨薪信息 | E17: 先查原文 | F17: 补文档 | G17: S2 | H17: 正确拒答可通过
A18: P2 | B18: 解析异常 | C18: 原文有但入库错乱 | D18: PDF表格错位 | E18: 对比原文件 | F18: Parser/OCR | G18: S1~S2
A19: P3 | B19: 检索/召回错误 | C19: 正确内容未进入TopK | D19: Top5没有差旅制度 | E19: 查检索结果 | F19: Embedding/TopK | G19: S1~S2
A20: P4 | B20: Chunk错误 | C20: 文档对但片段被切坏 | D20: 金额和适用城市被拆开 | E20: 检查Chunk完整性 | F20: Chunk策略 | G20: S2
A21: P5 | B21: 生成错误 | C21: 上下文对但答案错 | D21: 上下文明写500元，回答800元 | E21: 先确认上下文 | F21: LLM/Prompt | G21: S1~S2
A22: P6 | B22: 引用错误 | C22: 答案对但引错 | D22: 答案引用旧制度 | E22: 打开引用核对 | F22: Citation | G22: S2
A23: P7 | B23: 幻觉 | C23: 无证据却回答 | D23: 编造不存在的政策 | E23: 寻找证据 | F23: 拒答策略 | G23: S1
A24: P8 | B24: 多轮错误 | C24: 忘记前文 | D24: “那超过3天呢？”指代失败 | E24: 连续会话测试 | F24: 上下文 | G24: S2
A25: P9 | B25: 权限错误 | C25: 看到未授权资料 | D25: 普通员工看到管理层资料 | E25: 换角色验证 | F25: ACL/Tenant | G25: S0 | H25: 必须为0
A26: P10 | B26: UI/交互 | C26: 前端展示异常 | D26: 引用打不开 | E26: 检查交互 | F26: OpenWebUI UI | G26: S2~S3
A28: 说明：P1~P10 用于失败根因归类；本表中的严重级别仅为常见参考。最终 S0~S3 定级及通过/失败判定，以“05-评分与验收标准”为准。

Sheet 03-文档覆盖矩阵
A1: 文档类型与结构覆盖标准
A3: 文档类型 | B3: 典型结构/场景 | C3: 必须覆盖的解析点 | D3: 建议Case | E3: 重点风险 | F3: 是否需要视觉理解 | G3: ≤2MB优先 | H3: 备注
A4: Markdown | B4: 标题、列表、表格、代码块、链接 | C4: 标题正文关系、代码保真、表格可检索 | D4: 30 | E4: 代码/表格被切坏 | F4: 否 | G4: 是 | H4: 技术资料重点
A5: PDF | B5: 纯文本、双栏、表格、图文混排、扫描件 | C5: 阅读顺序、页眉页脚、表格、OCR | D5: 50 | E5: 顺序错乱/OCR失败 | F5: 部分 | G5: 是 | H5: 重点
A6: Excel | B6: 单/多Sheet、公式、合并单元格、宽表 | C6: Sheet名、表头与数据、公式结果、单位 | D6: 40 | E6: 行列语义丢失 | F6: 通常否 | G6: 是 | H6: 结构化问答重点
A7: Word | B7: 标题、表格、图片、目录、页眉页脚 | C7: 标题层级、表格、正文顺序、目录去重 | D7: 40 | E7: 表格丢失/目录污染 | F7: 部分 | G7: 是 | H7: 制度/方案常见
A8: 图片 | B8: 截图、扫描、流程图、架构图、表格图 | C8: OCR、图中关系、流程、文字区域 | D8: 40 | E8: 只识字不理解结构 | F8: 是 | G8: 是
A9: 混合 | B9: 同一知识库同时包含 Markdown/PDF/Excel/Word/图片 | C9: 跨格式检索、同主题多来源、版本冲突、引用来源准确性 | D9: 50 | E9: 召回偏向单一格式、同名内容冲突、引用错误 | F9: 视内容 | G9: 是 | H9: 必须专项覆盖
A11: 混合文档专项 | B11: 示例 | C11: 测试目标 | D11: 推荐题型 | E11: 通过标准 | F11: 失败可能 | G11: 建议数量 | H11: 备注
A12: 同主题多格式 | B12: HR制度PDF + FAQ.md + 审批Excel | C12: 看模型能否从多来源找到最合适答案 | D12: 跨文档、事实 | E12: 引用正确且答案一致 | F12: P3/P6 | G12: 10
A13: 新旧版本混合 | B13: 旧版Word + 新版PDF | C13: 能否优先使用最新版本 | D13: 版本冲突 | E13: 明确引用最新版本 | F13: P3/P5/P6 | G13: 10
A14: 规则+数据混合 | B14: 制度PDF + 标准表Excel | C14: 组合规则和数值 | D14: 跨格式推理 | E14: 规则与数值均正确 | F14: P3/P4/P5 | G14: 10
A15: 图文混合 | B15: 说明Word + 流程图PNG | C15: 是否能结合文字与图示 | D15: 流程、步骤 | E15: 关键步骤完整 | F15: P2/P3/P5 | G15: 10
A16: 同名相似内容 | B16: 多个部门同名SOP | C16: 能否利用知识库/Metadata区分来源 | D16: 精确范围题 | E16: 来源与部门匹配 | F16: P3/P6 | G16: 10

Sheet 04-文件大小策略
A1: 文件大小测试策略
A3: 日常 Golden Case 以 ≤2MB 文件为主（建议 80%～90%）。大文件只做少量边界专项，避免反复向量化造成 Token 和处理时间浪费。
A5: 大小档位 | B5: 测试定位 | C5: 建议覆盖 | D5: 主要测试内容 | E5: 日常回归 | F5: 向量化成本 | G5: 执行原则 | H5: 备注
A6: ≤2MB | B6: 日常主测试 | C6: 80%~90% | D6: 解析、召回、问答、引用、权限、多轮 | E6: 是 | F6: 低 | G6: Golden Dataset 默认使用
A7: 2~10MB | B7: 中等专项 | C7: 5%~10% | D7: 较长文档、多页、多Sheet | E7: 少量 | F7: 中 | G7: 每格式少量
A8: 10~30MB | B8: 大文件边界 | C8: 每格式1~3个 | D8: 上传、解析、Chunk数、首中尾召回 | E8: 否 | F8: 较高 | G8: 低频专项
A9: 30~100MB | B9: 压力边界 | C9: 整体2~5个 | D9: 稳定性、超时、索引时间、恢复 | E9: 否 | F9: 高 | G9: 重大变化时测试
A10: 100~200MB | B10: 极限专项 | C10: 1~2个固定样本 | D10: 首中尾覆盖、产品上限 | E10: 否 | F10: 很高 | G10: 非必要不重建
A11: >200MB | B11: 产品边界 | C11: 按实际支持 | D11: 拒绝策略、错误提示、系统保护 | E11: 否 | F11: 极高 | G11: 仅明确支持时测试
A13: 100MB级测试点 | B13: 示例 | C13: Case数 | D13: 频率 | E13: 通过标准 | F13: 归因 | G13: 大量问答？ | H13: 备注
A14: 上传/入库 | B14: 能否成功上传并完成索引 | C14: 1 | D14: 低频 | E14: 状态明确、无异常中断 | F14: P2/P10 | G14: 否 | H14: 记录耗时
A15: 首部召回 | B15: 询问前部明确事实 | C15: 1 | D15: 低频 | E15: 正确内容进入TopK | F15: P3/P4 | G15: 否
A16: 中部召回 | B16: 询问中部明确事实 | C16: 1 | D16: 低频 | E16: 正确内容进入TopK | F16: P3/P4 | G16: 否
A17: 尾部召回 | B17: 询问最后章节事实 | C17: 1 | D17: 低频 | E17: 正确内容进入TopK | F17: P3/P4 | G17: 否
A18: 复杂结构 | B18: 询问表格/图文内容 | C18: 1 | D18: 低频 | E18: 结构语义完整 | F18: P2/P4 | G18: 否
A19: 恢复 | B19: 必要时失败重试 | C19: 1 | D19: 极低频 | E19: 可恢复且错误明确 | F19: P2/P10 | G19: 否 | H19: 重大版本才执行

Sheet 05-评分与验收标准
A1: L1 评分与验收标准
A3: 统一规则：5分=完全符合预期；0分=本应支持但完全失败；N/A=该指标不适用，不参与评分。评分只用于统一测试口径，失败原因仍按 P1~P10 归因。
A5: 一、91-知识库测试Case：评分标准
A6: 指标 | B6: 5分 | C6: 4分 | D6: 3分 | E6: 2分 | F6: 1分 | G6: 0分 | H6: N/A | I6: 重点
A7: 正确性 | B7: 事实、条件、结论完全正确 | C7: 核心正确，仅轻微偏差 | D7: 核心基本正确，但有明显遗漏/次要错误 | E7: 部分正确，关键条件或结论有错 | F7: 仅少量内容正确，整体基本错误 | G7: 完全错误、答非所问或应答未答 | H7: 通常不适用 | I7: 优先看核心事实和业务规则
A8: 完整性 | B8: 全部关键点覆盖 | C8: 仅遗漏少量非关键细节 | D8: 主要关键点覆盖，但有明显遗漏 | E8: 遗漏多个关键点，需人工补充 | F8: 只覆盖极少关键点 | G8: 未回答或完全未覆盖关键点 | H8: 通常不适用 | I8: 先在标准答案中定义必答点
A9: 引用准确性 | B9: 来源、版本、章节均正确 | C9: 主要引用正确，仅轻微定位偏差 | D9: 主要来源正确，但部分结论缺引用/定位不准 | E9: 部分引用错误或引用旧版本 | F9: 大部分引用错误 | G9: 无引用或引用完全错误 | H9: 该 Case 不要求引用 | I9: 答案正确但引用旧版本也要扣分
A11: 二、92-文档解析Case：评分标准
A12: 指标 | B12: 5分 | C12: 4分 | D12: 3分 | E12: 2分 | F12: 1分 | G12: 0分 | H12: N/A | I12: 重点
A13: 标题层级 | B13: 标题层级与父子关系完全正确 | C13: 少量层级偏差，不影响理解 | D13: 有明显错误，但主要章节可识别 | E13: 多处层级错误，需要人工判断 | F13: 只有少量标题可识别 | G13: 标题结构完全丢失/严重错误 | H13: 无标题结构 | I13: H1/H2、Word Heading、章节归属
A14: 正文完整性 | B14: 无关键缺失、重复、乱码 | C14: 少量非关键缺失/噪声 | D14: 有明显缺失/重复，但主要信息完整 | E14: 关键段落缺失，影响部分问答 | F14: 仅少量正文可用 | G14: 正文无法解析或核心内容全缺失 | H14: 极少使用 | I14: 看缺失、重复、乱码
A15: 表格结构 | B15: 表头、行列、数值、单位关系均正确 | C15: 少量格式损失，不影响语义 | D15: 有明显结构问题，但主要数据仍可对应 | E15: 多处行列错位，需要人工推断 | F15: 仅少量表格内容可辨认 | G15: 表格丢失或关系完全错误 | H15: 无表格 | I15: PDF/Excel/Word 表格重点
A16: 代码/公式保真 | B16: 代码、命令、公式、符号完全正确 | C16: 少量格式变化，不影响语义/执行 | D16: 部分符号/格式问题，主要逻辑可理解 | E16: 关键符号/公式有错，影响使用 | F16: 大部分失真 | G16: 完全丢失或不可用 | H16: 无代码/公式 | I16: 技术文档和 Excel 重点
A17: 图片/OCR | B17: 关键文字、数字、关系均正确 | C17: 少量 OCR 错字，不影响含义 | D17: 有若干错误，但主要信息可理解 | E17: 关键字段/关系有错，明显影响理解 | F17: 只能识别少量有效内容 | G17: 完全不可用 | H17: 无图片/OCR内容 | I17: 流程图还要看节点与箭头关系
A18: 顺序正确性 | B18: 段落、页面、双栏、流程顺序完全正确 | C18: 少量顺序问题，不影响语义 | D18: 有明显问题，但主要上下文可恢复 | E18: 多处错乱，容易误解 | F18: 顺序基本不可用 | G18: 完全错乱 | H18: 通常不适用 | I18: 双栏 PDF、图文混排重点
A19: 来源定位信息 | B19: 文件名、标题、页码/Sheet、版本、来源均正确 | C19: 少量非关键 Metadata 缺失 | D19: 部分缺失，但仍可区分主要来源 | E19: 关键 Metadata 缺失，影响定位/版本判断 | F19: 仅保留极少 Metadata | G19: 全部缺失或错误 | H19: 链路明确不提供 | I19: 混合文档/版本冲突重点
A21: 三、最终结果判定
A22: 条件 | B22: 推荐结果 | C22: 严重级别 | D22: 适用Sheet | E22: 说明 | F22: 是否可例外 | G22: 例外要求 | H22: 示例 | I22: 备注
A23: 权限泄露=是 | B23: 失败 | C23: S0 | D23: 91 | E23: 安全红线，直接阻断 | F23: 否 | G23: 无 | H23: 普通用户看到无权限HR资料 | I23: 必须为0
A24: 明确幻觉 | B24: 失败 | C24: S1 | D24: 91 | E24: 无知识库依据却给出确定事实 | F24: 原则上否 | G24: 仅措辞争议时提供证据说明 | H24: 无涨薪资料却回答涨薪10%
A25: 正确性≤2 | B25: 失败 | C25: S1~S2 | D25: 91 | E25: 核心回答质量不足 | F25: 通常否 | G25: 特殊场景需备注 | H25: 关键金额答错
A26: 引用准确性≤2，且该题要求引用 | B26: 失败 | C26: S2，严重误导可S1 | D26: 91 | E26: 来源不足以支撑答案 | F26: 可 | G26: 必须说明仍可接受原因 | H26: 答案对但引用旧制度
A27: 91普通Case推荐通过线 | B27: 通过 | C27: — | D27: 91 | E27: 正确性≥4、完整性≥3、引用≥3或N/A，且无幻觉/权限问题 | F27: 可 | G27: 3分项需备注且不影响业务 | H27: 正常制度问答 | I27: 默认阈值
A28: 任一适用的关键解析项≤2，或关键内容不可检索 | B28: 失败 | C28: S1~S2 | D28: 92 | E28: 解析已影响可用性 | F28: 可 | G28: 仅非关键项不影响问答时可例外 | H28: PDF表格严重错位
A29: 92推荐通过线 | B29: 通过 | C29: — | D29: 92 | E29: 所有适用项原则上≥4，且关键内容可检索=是 | F29: 可 | G29: 允许非关键项=3但需备注 | H29: Markdown正常解析 | I29: 默认阈值
A30: 原文有答案且未找到正确内容
A31: 四、严重级别 S0～S3
A32: 级别 | B32: 定义 | C32: 典型场景 | D32: 是否阻断 | E32: 优先级 | F32: 示例 | G32: 常见归因 | H32: 处理动作 | I32: 备注
A33: S0 阻断 | B33: 安全、权限、数据泄露等不可接受问题 | C33: 越权读取、跨租户泄露 | D33: 是 | E33: 最高 | F33: 普通员工看到管理层私有资料 | G33: P9 | H33: 立即上报并停止相关验收 | I33: 必须为0
A34: S1 严重 | B34: 核心答案错误、明确幻觉、核心解析不可用 | C34: 关键金额错误、大面积OCR失败 | D34: 通常是 | E34: 高 | F34: 无依据编造政策 | G34: P2/P5/P7等 | H34: 优先修复并回归
A35: S2 一般 | B35: 局部错误，影响部分问题但可绕行 | C35: 召回失败、局部表格错位、引用旧版 | D35: 视目标 | E35: 中 | F35: 同义词召回失败 | G35: P3/P4/P6等 | H35: 正常登记并回归
A36: S3 轻微 | B36: 展示、定位或非关键细节问题 | C36: 轻微页码偏差、UI展示问题 | D36: 否 | E36: 低 | F36: 引用位置偏差但文档正确 | G36: P10等 | H36: 记录即可
A40: 五、其他判定字段填写规则
A41: 字段 | B41: 正常/是 | C41: 部分 | D41: 异常/否 | E41: 适用Sheet | F41: 最终结果影响 | G41: 填写要点 | H41: 参考 | I41: 备注
A42: 原文是否有答案 | B42: 是：原始文档中有明确证据支持标准答案 | C42: — | D42: 否：核对原始文档后确认无足够信息 | E42: 91 | F42: 决定该 Case 是正常回答题还是无答案/拒答题 | G42: 必须先看原始文档；不能因为 OpenWebUI 没答出来就填“否” | H42: 01-测试题来源指南
A43: 是否找到正确内容 | B43: 是：检索结果中有足够证据支持标准答案 | C43: 部分：只找到部分证据，缺关键条件/数值/上下文 | D43: 否：未找到能支持标准答案的正确内容 | E43: 91 | F43: 用于区分检索问题与生成问题 | G43: 原文有答案但未召回 → 优先看 P3/P4；已正确召回但回答错误 → 优先看 P5 | H43: 02-RAG术语与归因 | I43: 无答案 Case 可填“无法判断”
A44: 关键内容可检索 | B44: 是：预期关键内容均可通过知识库检索找到 | C44: 部分：只有部分关键内容可检索 | D44: 否：关键内容无法检索 | E44: 92 | F44: 否 → 默认失败；部分 → 根据关键性判断 | G44: 重点看“预期结构/关键内容”中定义的关键内容，而不是只看文档是否成功上传 | H44: 本Sheet第3部分最终结果判定
A45: 失败归因（负责人） | B45: 通过 Case 可留空 | C45: — | D45: 失败/需回归 Case 应选择最主要的 P1~P10 | E45: 91 | F45: 不直接决定通过/失败，但失败 Case 必须可定位 | G45: 测试人员只填“异常现象”；负责人结合对话、检索/解析信息选择主要 P1~P10，其他问题写备注 | H45: 02-RAG术语与归因
A46: 异常现象 | B46: 无明显异常 | C46: — | D46: 从下拉中选择最接近的可观察现象 | E46: 91 | F46: 帮助负责人快速复核，不等同于技术根因 | G46: 测试人员只描述“看到什么”：回答错误、引用错误、疑似未找到知识、疑似幻觉等；不要判断 Embedding/Chunk/模型根因 | H46: 91-知识库测试Case | I46: 最终 P1~P10 由负责人填写
A48: 六、91 评分锚定示例
...

Sheet 90-测试批次配置
A1: 测试人员填写：测试批次 / Configuration Fingerprint
A3: Run ID | B3: 批次日期 | C3: 批次负责人 | D3: 自定义模型 | E3: 自定义模型版本 | F3: OpenWebUI版本 | G3: Base Model Provider | H3: Base Model | I3: System Prompt版本 | J3: Knowledge Base | K3: Knowledge版本 | L3: Embedding Model | M3: Reranker | N3: Top K | O3: Skills/Tools | P3: 备注
A4: RUN-L1-001 | C4: 测试人员A | D4: 行政知识助手 | E4: v1 | F4: v0.11.0 | G4: OpenAI | H4: gpt-example-a | I4: prompt-v1 | J4: 行政制度知识库 | K4: kb-2026-08 | L4: text-embedding-v4 | M4: 无 | N4: 3 | O4: 关闭 | P4: 示例：行政制度常规测试
A5: RUN-L1-002 | C5: 测试人员B | D5: HR知识助手 | E5: v1 | F5: v0.11.0 | G5: OpenAI | H5: gpt-example-a | I5: prompt-v1 | J5: HR制度知识库 | K5: kb-2026-08 | L5: text-embedding-v4 | M5: 无 | N5: 3 | O5: 关闭 | P5: 示例：HR 制度常规测试
A6: RUN-L1-003 | C6: 测试人员C | D6: 企业综合知识助手 | E6: v2 | F6: v0.11.0 | G6: OpenAI | H6: gpt-example-a | I6: prompt-v2 | J6: 企业综合知识库 | K6: kb-2026-08 | L6: text-embedding-v4 | M6: 无 | N6: 3 | O6: 关闭 | P6: 示例：PDF+Markdown+Excel 混合知识库
A7: RUN-L1-004 | C7: 测试人员A | D7: IT运维知识助手 | E7: v1 | F7: v0.11.0 | G7: OpenAI | H7: gpt-example-b | I7: prompt-v1 | J7: IT运维知识库 | K7: kb-2026-08 | L7: text-embedding-v4 | M7: 无 | N7: 3 | O7: 关闭 | P7: 示例：对比不同 Base Model 前先固定 L1 配置
A8: RUN-L1-008 | B8: 2026-08-20 | C8: 测试人员A | D8: yxc-职业道德规范知识库测试 | E8: v1 | F8: v0.11.0 | I8: 默认 | J8: 职业道德规范 | M8: 无 | O8: 内置工具(Native函数调用) | P8: 网页等价链路（native+session_id 内置工具 query/grep 自动执行），每题独立新会话（多轮组 M01/M02/M03 组内连续追问），记录完整工具调用/思考/引用过程

Sheet 91-知识库测试Case
A1: Case ID | B1: Run ID | C1: 执行日期 | D1: 执行测试人员 | E1: 知识库(同 90) | F1: 文档类型 | G1: 文档名称/组合 | H1: 文件大小档位 | I1: 问题类型 | J1: 难度 | K1: 用户问题 | L1: 原文是否有答案 | M1: 标准答案/关键点 | N1: 标准来源 | O1: OpenWebUI实际回答 | P1: 实际引用 | Q1: OpenWebUI对话链接 | R1: 是否找到正确内容 | S1: 异常现象 | T1: 正确性(0-5) | U1: 完整性(0-5) | V1: 引用准确性(0-5) | W1: 是否幻觉 | X1: 是否权限泄露 | Y1: 最终结果 | Z1: 失败归因（负责人） | AA1: 严重级别（负责人） | AB1: 备注/回归信息
A2: EX-L1-001 | B2: RUN-L1-001 | D2: 测试人员A | E2: =IFERROR(VLOOKUP(B2,'90-测试批次配置'!$A$4:$P$200,10,FALSE),"") | F2: PDF | G2: 差旅管理制度.pdf | H2: ≤2MB | I2: 事实查询 | J2: 简单 | K2: 出差到一线城市，普通员工住宿最高能报多少？ | L2: 是 | M2: 应回答内部制度中规定的一线城市普通员工住宿上限，例如 600 元/晚；具体以测试文档内容为准。 | N2: 差旅管理制度 / 住宿标准章节 | O2: 根据《差旅管理制度》，普通员工在一线城市住宿标准上限为 600 元/晚。 | P2: 差旅管理制度.pdf / 住宿标准章节 | Q2: https://openwebui.example/chat/EX-L1-001 | R2: 是 | S2: 无明显异常 | T2: 5 | U2: 5 | V2: 5 | W2: 否 | X2: 否 | Y2: 通过 | AB2: 示例：正常 Case。普通通过 Case 的对话链接建议填写。
A3: EX-L1-002 | B3: RUN-L1-001 | D3: 测试人员B | E3: =IFERROR(VLOOKUP(B3,'90-测试批次配置'!$A$4:$P$200,10,FALSE),"") | F3: PDF | G3: 差旅管理制度.pdf | H3: ≤2MB | I3: 同义词/语义 | J3: 中等 | K3: 出差住酒店最多能报销多少钱？ | L3: 是 | M3: 应理解“住酒店”与“住宿标准”为同一语义，并召回住宿报销上限。 | N3: 差旅管理制度 / 住宿标准章节 | O3: 根据当前知识库，未找到明确的酒店报销金额规定。 | P3: 未引用正确文档 | Q3: https://openwebui.example/chat/EX-L1-002 | R3: 否 | S3: 疑似未找到知识 | T3: 1 | U3: 1 | V3: 0 | W3: 否 | X3: 否 | Y3: 失败 | Z3: P3 检索/召回错误 | AA3: S2 一般 | AB3: 示例：失败 Case 对话链接必填，方便研发复现检索结果。
A4: EX-L1-003 | B4: RUN-L1-002 | D4: 测试人员C | E4: =IFERROR(VLOOKUP(B4,'90-测试批次配置'!$A$4:$P$200,10,FALSE),"") | F4: Word | G4: 员工福利制度.docx | H4: ≤2MB | I4: 无答案问题 | J4: 中等 | K4: 公司明年会统一涨薪 10% 吗？ | L4: 否 | M4: 知识库没有明确涨薪计划时，应说明无法依据当前知识库判断。 | N4: 无 | O4: 当前知识库中没有关于明年统一涨薪 10% 的明确计划，因此无法据此确认。 | P4: 无 | Q4: https://openwebui.example/chat/EX-L1-003 | R4: 无法判断 | S4: 无明显异常 | T4: 5 | U4: 5 | V4: N/A | W4: 否 | X4: 否 | Y4: 通过 | AB4: 示例：无答案题正确拒答属于通过。
A5: EX-L1-004 | B5: RUN-L1-002 | D5: 测试人员A | E5: =IFERROR(VLOOKUP(B5,'90-测试批次配置'!$A$4:$P$200,10,FALSE),"") | F5: Word | G5: 员工福利制度.docx | H5: ≤2MB | I5: 无答案问题 | J5: 中等 | K5: 公司明年会统一涨薪 10% 吗？ | L5: 否 | M5: 知识库没有相关计划，应拒答。 | N5: 无 | O5: 是的，公司计划明年统一涨薪 10%。 | P5: 员工福利制度.docx，但原文并无该内容 | Q5: https://openwebui.example/chat/EX-L1-004 | R5: 否 | S5: 疑似幻觉 | T5: 0 | U5: 0 | V5: 0 | W5: 是 | X5: 否 | Y5: 失败 | Z5: P7 幻觉 | AA5: S1 严重 | AB5: 示例：知识库没有依据却给出确定答案，属于幻觉；链接必填。
A6: EX-L1-005 | B6: RUN-L1-003 | D6: 测试人员B | E6: =IFERROR(VLOOKUP(B6,'90-测试批次配置'!$A$4:$P$200,10,FALSE),"") | F6: 混合 | G6: 员工手册.pdf + 请假FAQ.md + 审批矩阵.xlsx | H6: 混合大小 | I6: 跨文档 | J6: 困难 | K6: 员工请假超过 3 天，需要经过哪些审批？ | L6: 是 | M6: 应综合员工手册中的规则、FAQ 中的补充说明和审批矩阵中的审批链，给出完整流程。 | N6: 员工手册 / 请假章节；请假FAQ.md；审批矩阵.xlsx | O6: 超过 3 天的请假，需要直属主管和部门负责人审批；若达到制度规定的更长期限，还需 HR 审批。 | P6: 员工手册.pdf + 审批矩阵.xlsx | Q6: https://openwebui.example/chat/EX-L1-005 | R6: 是 | S6: 无明显异常 | T6: 5 | U6: 4 | V6: 5 | W6: 否 | X6: 否 | Y6: 通过 | AB6: 示例：混合文档 Case，文档名称/组合要写清参与文件。
A7: EX-L1-006 | B7: RUN-L1-003 | D7: 测试人员C | E7: =IFERROR(VLOOKUP(B7,'90-测试批次配置'!$A$4:$P$200,10,FALSE),"") | F7: 混合 | G7: 旧版差旅制度.docx + 新版差旅制度.pdf | H7: ≤2MB | I7: 版本冲突 | J7: 困难 | K7: 当前最新的一线城市住宿标准是多少？ | L7: 是 | M7: 应优先依据新版差旅制度回答，并引用新版文档。 | N7: 新版差旅制度.pdf / 住宿标准章节 | O7: 当前标准为 600 元/晚。 | P7: 旧版差旅制度.docx / 住宿标准章节 | Q7: https://openwebui.example/chat/EX-L1-006 | R7: 是 | S7: 引用错误 | T7: 5 | U7: 5 | V7: 1 | W7: 否 | X7: 否 | Y7: 失败 | Z7: P6 引用错误 | AA7: S2 一般 | AB7: 示例：答案数值正确但引用旧版本，仍判引用错误；链接必填。
A8: L1-0001 | B8: RUN-L1-008 | C8: 2026-08-20 | D8: 测试人员A | E8: =IFERROR(VLOOKUP(B8,'90-测试批次配置'!$A$4:$P$200,10,FALSE),"") | F8: PDF/DOCX | G8: 反商业贿赂制度V1.0.pdf；员工道德规范准则.pdf | H8: ≤2MB | I8: 跨段跨文档 | J8: 难 | K8: 员工收了供应商送的礼品,按照两个制度分别应如何处理? | L8: 是 | M8: 按《员工道德规范准则》3.1条:不得接受与公司有业务往来的组织/个人提供的报酬、馈赠、金钱、贷款、服务、礼品等,也不得安排其亲属、朋友接受。按《反商业贿赂制度》3.11条:根据违反行为的性质、情节轻重及造成的后果,采取口头警告、书面警告、罚款、解除劳动合同、移交司法机关等处理措施;3.9条还规定执行承诺书情况作为考察、考核、任免的重要依据。 | N8: 反商业贿赂制度V1.0.pdf；员工道德规范准则.pdf /DOC2 3.1 / DOC1 3.11 + 3.9 | O8: # 员工收受供应商礼品的处理(按两个制度) ## 一、按《反商业贿赂制度V1.0》 该制度禁止任何形式的商业贿赂行为,并要求员工签署《反商业贿赂承诺书(员工版)》[1]。若员工收受供应商礼品构成违规,公司将根据行为性质、情节轻重及后果,采取以下一种或多种处理措施 [1]: 1. **口头警告**:情节轻微、未造成实际损失的,口头警告并要求立即改正; 2. **书面警告**:情节较重但未造成重大损失的,书面警告并记入个人档案; 3. **罚款**:情节严重、造成一定经济损失的,按损失程度罚款; 4. **解除劳动合同**:严重违反制度、造成重大损失或恶劣影响,或屡教不改的; 5. **移交司法机关**:构成犯罪的商业贿赂行为,依法追究刑事责任。 此外,若涉事员工为采购、销售人员,一经发现通过商业贿赂行为开展采购、销售活动,应从严追究责任并终止其采购或销售资格;相关行为还将记入个人反商业贿赂档案,影响年终业绩考评和续聘 [1]。 ## 二、按《员工道德规范准则》 准则第 3.1 条明确:员工**不得接受**与公司有业务往来的或正在寻求与公司进行交易的组织/个人(即包括供应商)提供的报酬、馈赠、金钱、礼品等利益,也不得安排亲属、朋友接受上述利益 [2]。同时,员工就实际发生的利益冲突应主动、及时、如实向公司 CEO 和 CFO 报告(专用邮箱 kpwh@kaopuyun.com),或先向直接主管报告;不确定是否存在利益冲突时,也应向直接主管或 CEO、CFO 询问,并向法务部报告以便审查 [2]。 ## 简要结论 - 收受供应商礼品在两个制度下均属**明令禁止**的行为; - 《反商业贿赂制度》侧重于事后追责(警告→罚款→解约→移送司法的阶梯式处理)[1]; - 《员工道德规范准则》侧重于**事前禁止和主动申报**——即便已收受,也应主动向 CEO/CFO 及法务部如实报告并妥善处理 [2]。 | P8: 员工道德规范准则.pdf:L19｜3.1.不得接受竞争对手、与公司有业务往来的或正在寻求与公司进行交易的组织/个人提供的报酬、馈赠、金钱、贷款、服务、礼品等,也不得安排其亲属、朋友接受上述利益。; 反商业贿赂制度V1.0.pdf:L1｜## 反商业贿赂制度\n2c15d011-ed12-4d9e-9f72-4f857ede2dca 反商业贿赂制度V1.0.pdf:5: 为扎实推进商业活动的反 | Q8: http://192.168.151.14:3000/c/f9a14276-56b3-4e12-8771-45bbe4345936 | R8: 是 | S8: 无明显异常 | T8: 5 | U8: 5 | V8: 5 | W8: 否 | X8: 否 | Y8: 通过
A9: L1-0002 | B9: RUN-L1-008 | C9: 2026-08-20 | D9: 测试人员A | E9: =IFERROR(VLOOKUP(B9,'90-测试批次配置'!$A$4:$P$200,10,FALSE),"") | F9: PDF/DOCX | G9: 反商业贿赂制度V1.0.pdf；员工道德规范准则.pdf | H9: ≤2MB | I9: 跨段跨文档 | J9: 难 | K9: 员工发现同事收受贿赂,有哪些举报渠道?各渠道的联系信息是什么? | L9: 是 | M9: 有两个举报渠道:1)反商业贿赂管理小组:电话18950299832,邮箱Fanhl@kaopuycloud.com(《反商业贿赂制度》3.14条),适用于商业贿赂类举报;2)利益冲突专用邮箱:kpwh@kaopuyun.com(《员工道德规范准则》3.8条),可发送至公司CEO和CFO,适用于利益冲突类举报。此外还可向直接主管报告或向法务部报告。 | N9: 反商业贿赂制度V1.0.pdf；员工道德规范准则.pdf /DOC1 3.14 / DOC2 3.8 | O9: 根据公司《反商业贿赂制度V1.0》和《员工道德规范准则》,针对同事收受贿赂等腐败行为的举报渠道如下: ## 举报渠道及联系信息 **1. 反商业贿赂管理小组(专门受理举报)** - 📞 电话:**18950299832** - 📧 邮箱:**Fanhl@kaopucloud.com** - 依据:《反商业贿赂制度》第3.14条 **2. 利益冲突专用报告邮箱** - 📧 邮箱:**kpwh@kaopuyun.com** - 用途:向公司 CEO 和 CFO 报告利益冲突、竞争行为等问题 - 依据:《员工道德规范准则》第3.8条 **3. 其他途径** - 向**直接主管**报告 - 直接向公司 **CEO 和 CFO** 报告 - 向**公司法务部**报告,由法务部审查处理 ## 举报人保护与奖励 - **严格保密**:举报受理、调查各环节严格保密,严禁泄露举报人姓名、部门等信息,严禁将举报情况透露给被举报人或部门(第3.12条) - **禁止打击报复**:违者将被追究责任(第3.13条) - **举报奖励**:经查证属实,奖励500元至5万元,或按挽回损失的5%计算,最高不超过5万元(第3.13条) 如发现此类行为,建议优先通过反商业贿赂管理小组的电话或邮箱举报,以确保专业受理和保密处理。 | P9: 反商业贿赂制度V1.0.pdf:L59｜3.12 公司鼓励员工及与公司有业务往来的公司检举揭发腐败行为,检举的受理、调查等各个环节,必须严格保密,严禁泄露检举人的姓名、部门、公司名称等信息,严禁将举报; 员工道德规范准则.pdf:L3｜为建立良好的企业氛围、商业秩序,营造良好的发展环境,纠正行业不正之风,杜绝商业贿赂活动,倡导诚实守信、尽职尽责的道德理念和行为准则,努力追求客户、股东、员工和社 | Q9: http://192.168.151.14:3000/c/2efeff91-8957-4f73-98b0-2c538a47895b | R9: 是 | S9: 无明显异常 | T9: 5 | U9: 5 | V9: 5 | W9: 否 | X9: 否 | Y9: 通过
A10: L1-0003 | B10: RUN-L1-008 | C10: 2026-08-20 | D10: 测试人员A | E10: =IFERROR(VLOOKUP(B10,'90-测试批次配置'!$A$4:$P$200,10,FALSE),"") | F10: PDF/DOCX | G10: 反商业贿赂制度V1.0.pdf | H10: ≤2MB | I10: 跨段跨文档 | J10: 难 | K10: 公司领导层和普通员工在反商业贿赂中各自承担什么责任? | L10: 是 | M10: 公司领导层(4.1条):1)必须学习掌握国家反商业贿赂政策;2)制定和完善反商业贿赂长效工作机制;3)部门、职位、人员设置明确合理;4)模范遵守和执行国家政策,接受监督;5)负有本公司反商业贿赂责任;6)加强企业动态监管;7)每年对反商业贿赂情况进行检查考评。普通员工(3.4条):1)严格履行签署的承诺书;2)禁止任何形式的商业贿赂行为;3)自觉接受预防商业贿赂监管小组的管理;4)违反相关承诺服从监督管理小组处理。 | N10: 反商业贿赂制度V1.0.pdf /4.1 / 3.4 | O10: 根据《反商业贿赂制度V1.0》的规定,公司领导层和普通员工在反商业贿赂中承担的责任如下: ## 一、公司领导层的责任(第4.1条) 领导层包括总经理及其他领导班子成员,其主要责任包括: 1. **学习掌握政策**:认真学习和掌握国家有关反商业贿赂及廉政建设的政策、文件精神,用以指导日常生产经营活动; 2. **建立长效机制**:根据公司实际情况制定和完善反商业贿赂的长效工作机制,从制度上确保经营活动合法、合理、公正; 3. **合理设置职责**:部门、职位、人员设置要明确合理、职责划分清晰,做到事有人管、责有人负、层层落实; 4. **模范遵守执行**:模范遵守和执行党和国家有关政策,接受有关部门和社会监督,发现问题勇于主动纠正,被检查发现问题要积极配合查处; 5. **承担管理责任**:领导层负有本公司反商业贿赂责任,一旦出现商业贿赂问题,根据职责分工分别承担责任; 6. **动态监管追责**:加强对企业的动态监管,对员工违反商业贿赂规定的行为按公司制度予以追究,情节严重的报请司法机关依法处理; 7. **年度检查完善**:每年对反商业贿赂制度实施情况进行检查考评,发现不足、找出漏洞并进一步完善。[1] ## 二、普通员工的责任 1. **签订承诺书**:员工应与公司签订《反商业贿赂承诺书(员工版)》,自签字盖章之日起生效;离职后,若在职期间存在商业贿赂行为,公司保留追溯权,承诺书失效不影响追责; 2. **违规处理**:员工违反本制度的,公司将根据行为性质、情节轻重及后果采取处理措施; 3. **检举义务与保护**:公司鼓励员工检举揭发腐败行为,并对检举人信息严格保密; 4. **岗位专项责任**: - **采购、销售人员**:不得有行贿、索贿、受贿行为,不得与供应商串通损害公司利益,不得以商业贿赂手段开展恶意竞争;通过商业贿赂开展业务的一经发现从严追责并终止资格; - **会计出纳人员**:坚持原则、自觉抵制做假账,发现涉及商业贿赂的账目问题要及时举报,对商业贿赂行为视而不见、不抵制不举报的将被曝光并惩戒。[1] **总结**:领导层承担制度建设、监督管理和问责的"管理责任",员工则承担依法依规执业、签订承诺书和举报违规行为的"直接执行责任"。[1] | P10: 反商业贿赂制度V1.0.pdf:L14｜3.1 公司员工应与公司签订《反商业贿赂承诺书(员工版)》,此承诺书自签字盖章之日起生效,自劳动合同解除时自动失效。 \n2c15d011-ed12-4d9e | Q10: http://192.168.151.14:3000/c/a5c5399d-4d03-4488-9d83-61032845082e | R10: 是 | S10: 表述与标准答案不同 | T10: 4 | U10: 5 | V10: 5 | W10: 否 | X10: 否 | Y10: 通过 | AB10: 引用命中但回答表述与标准答案不同，建议人工核查。标准答案：公司领导层(4.1条):1)必须学习掌握国家反商业贿赂政策;2)制定和完善反商业贿赂长效工作机制;3
A11: L1-0004 | B11: RUN-L1-008 | C11: 2026-08-20 | D11: 测试人员A | E11: =IFERROR(VLOOKUP(B11,'90-测试批次配置'!$A$4:$P$200,10,FALSE),"") | F11: PDF/DOCX | G11: 反商业贿赂制度V1.0.pdf；员工道德规范准则.pdf | H11: ≤2MB | I11: 跨段跨文档 | J11: 难 | K11: 员工离职后,在职期间的商业贿赂行为和保密义务分别如何处理? | L11: 是 | M11: 商业贿赂(《反商业贿赂制度》3.2条):员工离职后,若在职期间存在商业贿赂行为,公司保留追溯权,承诺书失效不影响已发生行为的追责。保密义务(《员工道德规范准则》4.8条):员工保密义务在离职后的一定期限内仍然有效,义务持续期根据公平原则结合具体情况由公司决定。两者在离职后均不自动免除。 | N11: 反商业贿赂制度V1.0.pdf；员工道德规范准则.pdf /DOC1 3.2 / DOC2 4.8 | O11: 根据公司相关制度，员工离职后的处理方式如下： **一、商业贿赂行为** 员工在职期间存在商业贿赂行为的，即使已经离职，公司仍**保留追溯权**——《反商业贿赂承诺书》自劳动合同解除时自动失效，但承诺书的失效不影响对离职前已发生商业贿赂行为的追责 [1]。 **二、保密义务** 员工的保密义务在其离职后的**一定期限内仍然有效**，义务持续期根据公平原则、结合具体情况由公司决定 [2]。也就是说，离职并不能免除保密义务，员工在离职后仍须继续履行，如因泄密给公司造成损失的，除赔偿损失外，公司还将依照有关程序进行处分或追究法律责任 [2]。 | P11: 反商业贿赂制度V1.0.pdf:L15｜3.2 员工离职后,若在职期间存在商业贿赂行为,公司保留追溯权,承诺书失效不影响已发生行为的追责。 \n50477ce8-acfb-40a9-a8ad-c6a | Q11: http://192.168.151.14:3000/c/70d94678-3b29-4dac-a40c-59ddc02c37e5 | R11: 是 | S11: 表述与标准答案不同 | T11: 4 | U11: 5 | V11: 5 | W11: 否 | X11: 否 | Y11: 通过 | AB11: 引用命中但回答表述与标准答案不同，建议人工核查。标准答案：商业贿赂(《反商业贿赂制度》3.2条):员工离职后,若在职期间存在商业贿赂行为,公司保留追溯权,承诺
A12: L1-0005 | B12: RUN-L1-008 | C12: 2026-08-20 | D12: 测试人员A | E12: =IFERROR(VLOOKUP(B12,'90-测试批次配置'!$A$4:$P$200,10,FALSE),"") | F12: PDF/DOCX | G12: 员工道德规范准则.pdf | H12: ≤2MB | I12: 跨段跨文档 | J12: 难 | K12: 利益冲突的具体情形有哪些?发现后应如何报告? | L12: 是 | M12: 具体情形(3.5/3.6条):1)具有实质性财务利益的利益关系;2)存在特惠债务的利益关系;3)在私下和约或谅解协议中约定的利益关系;4)员工及主要近亲属自营或为他人经营与公司竞争的业务;5)员工及主要近亲属与公司形成业务往来;6)员工与竞争组织存在聘任或劳务关系。报告流程(3.8条):1)向公司CEO和CFO如实报告,可发送至kpwh@kaopuyun.com;2)不确定时向直接主管报告或直接向CEO和CFO报告;3)情况变化时及时报告;4)向法务部报告以便审查。 | N12: 员工道德规范准则.pdf /3.5 / 3.6 / 3.8 | O12: 根据《员工道德规范准则》第3条,利益冲突的具体情形和报告方式如下: ## 一、利益冲突的具体情形 **利益关系方面 [1]:** - 具有实质性财务利益的利益关系 - 存在特惠债务的利益关系 - 在私下和约或谅解协议中约定的利益关系 **竞争行为及其他情形 [1]:** - 员工(包括董事和高管)和/或其主要近亲属自营、为他人经营或参与经营与公司直接或间接竞争的任何业务 - 员工和/或其主要近亲属(包括其经营的公司)与公司形成任何形式的业务往来 - 员工与公司构成竞争关系的组织/个人、或与公司有业务往来的组织/个人存在聘任关系、劳务关系或活动 **其他禁止性行为 [1]:** - 接受竞争对手、业务往来方提供的报酬、馈赠、金钱、贷款、服务、礼品等(包括安排亲属朋友接受) - 利用职务之便收受同事贿赂、谋取私利 - 利用职务之便获取不应得的利益(如虚假报销) - 未经公司审批,获取、转移、售卖公司实体或虚拟产品 此外,董事或高管从事可能涉及利益冲突的交易或关系,须提前获得审计委员会书面同意 [1]。 ## 二、发现后的报告方式 [1] 1. **主动报告**:员工应主动、及时就实际发生的、潜在的利益冲突及竞争行为,如实向公司 CEO 和 CFO 报告,可直接发送至专用邮箱:kpwh@kaopuyun.com 2. **不确定时询问**:无法确定是否与公司利益冲突时,应向直接主管提交报告,或直接向 CEO 和 CFO 报告 3. **情况变化时更新**:报告中的情况发生变化时,应及时向直接主管或 CEO、CFO 报告 4. **法务部审查**:向公司法务部报告潜在的利益冲突和/或竞争行为,由法务部审查并做出决定 | P12: 员工道德规范准则.pdf:L17｜## 3. 利益冲突原则\n50477ce8-acfb-40a9-a8ad-c6ae467fa3ad 员工道德规范准则.pdf:28: 3.6.员工不得从事与 | Q12: http://192.168.151.14:3000/c/ee7ca04b-e271-471d-a4ce-e3a1c9d76771 | R12: 是 | S12: 表述与标准答案不同 | T12: 4 | U12: 5 | V12: 5 | W12: 否 | X12: 否 | Y12: 通过 | AB12: 引用命中但回答表述与标准答案不同，建议人工核查。标准答案：具体情形(3.5/3.6条):1)具有实质性财务利益的利益关系;2)存在特惠债务的利益关系;3)在私
A13: L1-0006 | B13: RUN-L1-008 | C13: 2026-08-20 | D13: 测试人员A | E13: =IFERROR(VLOOKUP(B13,'90-测试批次配置'!$A$4:$P$200,10,FALSE),"") | F13: PDF/DOCX | G13: 反商业贿赂制度V1.0.pdf | H13: ≤2MB | I13: 跨段跨文档 | J13: 难 | K13: 公司对举报人有哪些保护措施?举报有什么奖励? | L13: 是 | M13: 保护措施(3.12条):1)检举的受理、调查等各环节严格保密;2)严禁泄露检举人姓名、部门、公司名称等信息;3)严禁将举报情况透露给被举报人或部门;4)调查核实时不得出示检举材料原件或复印件,不得暴露检举人;5)匿名检举不得鉴定笔迹;6)检举材料不得随意对外借阅;7)禁止任何形式的打击报复,违者追究责任(3.13条)。奖励(3.13条):对提供真实有效举报信息且经查证属实的举报人给予奖励,金额为500元至5万元,或按挽回损失的5%计算,最高不超过5万元。 | N13: 反商业贿赂制度V1.0.pdf /3.12 / 3.13 | O13: 根据《反商业贿赂制度V1.0》相关规定： **举报人保护措施（第3.12条）** - 检举的受理、调查等各个环节必须**严格保密**，严禁泄露检举人的姓名、部门、公司名称等信息； - 严禁将举报情况透露给被举报人或部门； - 调查核实情况时，不得出示检举材料原件或复印件，不得暴露检举人； - 对匿名的检举书信及材料，不得鉴定笔迹； - 检举材料不得随意对外借阅； - **禁止任何形式的打击报复**，违者将追究责任。 **举报奖励（第3.13条）** - 公司设立举报奖励机制，对提供真实有效举报信息且**经查证属实**的举报人给予奖励； - 根据举报内容的价值和贡献，奖励金额为 **500元至5万元**，或按**挽回损失的5%** 计算，最高不超过5万元。 | P13: 反商业贿赂制度V1.0.pdf:L59｜3.12 公司鼓励员工及与公司有业务往来的公司检举揭发腐败行为,检举的受理、调查等各个环节,必须严格保密,严禁泄露检举人的姓名、部门、公司名称等信息,严禁将举报 | Q13: http://192.168.151.14:3000/c/10ca6ef9-a562-46e2-bcaf-a8fa4bc17894 | R13: 是 | S13: 无明显异常 | T13: 5 | U13: 5 | V13: 5 | W13: 否 | X13: 否 | Y13: 通过
A14: L1-0007 | B14: RUN-L1-008 | C14: 2026-08-20 | D14: 测试人员A | E14: =IFERROR(VLOOKUP(B14,'90-测试批次配置'!$A$4:$P$200,10,FALSE),"") | F14: PDF/DOCX | G14: 反商业贿赂制度V1.0.pdf | H14: ≤2MB | I14: 直接事实 | J14: 易 | K14: 《反商业贿赂制度》的生效日期是哪一天? | L14: 是 | M14: 本制度自2025年04月01日起生效。 | N14: 反商业贿赂制度V1.0.pdf /6.3 附则 / 修订履历表 | O14: 《反商业贿赂制度》(V1.0)自 **2025年04月01日** 起生效（见文件第6.3条）。 | P14: 反商业贿赂制度V1.0.pdf:L1,14｜## 反商业贿赂制度\n2c15d011-ed12-4d9e-9f72-4f857ede2dca 反商业贿赂制度V1.0.pdf:14: 3.1 公司员工应与 | Q14: http://192.168.151.14:3000/c/5d784c25-a813-47b6-a5d1-20cbc3295f14 | R14: 是 | S14: 无明显异常 | T14: 5 | U14: 5 | V14: 5 | W14: 否 | X14: 否 | Y14: 通过
A15: L1-0008 | B15: RUN-L1-008 | C15: 2026-08-20 | D15: 测试人员A | E15: =IFERROR(VLOOKUP(B15,'90-测试批次配置'!$A$4:$P$200,10,FALSE),"") | F15: PDF/DOCX | G15: 反商业贿赂制度V1.0.pdf | H15: ≤2MB | I15: 直接事实 | J15: 中 | K15: 公司反商业贿赂管理小组的联系电话和邮箱分别是什么? | L15: 是 | M15: 电话:18950299832,邮箱:Fanhl@kaopuycloud.com。 | N15: 反商业贿赂制度V1.0.pdf /3.14 | O15: 根据《反商业贿赂制度V1.0》第3.14条: - **联系电话**:18950299832 - **邮箱**:Fanhl@kaopucloud.com | P15: 反商业贿赂制度V1.0.pdf:L61｜3.14 公司反商业贿赂管理小组人员电话:【18950299832】,邮箱【Fanhl@kaopucloud.com】'}] | Q15: http://192.168.151.14:3000/c/b0b51000-2e5f-4604-878d-8be655f89b9d | R15: 是 | S15: 无明显异常 | T15: 5 | U15: 5 | V15: 5 | W15: 否 | X15: 否 | Y15: 通过
A16: L1-0009 | B16: RUN-L1-008 | C16: 2026-08-20 | D16: 测试人员A | E16: =IFERROR(VLOOKUP(B16,'90-测试批次配置'!$A$4:$P$200,10,FALSE),"") | F16: PDF/DOCX | G16: 反商业贿赂制度V1.0.pdf | H16: ≤2MB | I16: 直接事实 | J16: 中 | K16: 公司举报奖励的金额范围是多少? | L16: 是 | M16: 奖励金额为500元至5万元,或按挽回损失的5%计算,最高不超过5万元。 | N16: 反商业贿赂制度V1.0.pdf /3.13 | O16: 根据《反商业贿赂制度V1.0》第3.13条: **公司举报奖励的金额范围为 500元至5万元**,或按挽回损失的5%计算,最高不超过5万元。 补充说明: - 奖励对象:提供真实有效举报信息且经查证属实的举报人 - 奖励依据:根据举报内容的价值和贡献确定 - 保密保障:公司对举报人信息严格保密,禁止任何形式的打击报复,违者将追究责任 | P16: 反商业贿赂制度V1.0.pdf:L60｜3.13 公司设立举报奖励机制,对提供真实有效举报信息且经查证属实的举报人给予奖励。根据举报内容的价值和贡献,奖励金额为500元至5万元,或按挽回损失的5%计算 | Q16: http://192.168.151.14:3000/c/5bea7f52-f211-468a-ad3d-829695fb0c27 | R16: 是 | S16: 无明显异常 | T16: 5 | U16: 5 | V16: 5 | W16: 否 | X16: 否 | Y16: 通过
A17: L1-0010 | B17: RUN-L1-008 | C17: 2026-08-20 | D17: 测试人员A | E17: =IFERROR(VLOOKUP(B17,'90-测试批次配置'!$A$4:$P$200,10,FALSE),"") | F17: PDF/DOCX | G17: 员工道德规范准则.pdf | H17: ≤2MB | I17: 直接事实 | J17: 中 | K17: 员工利益冲突专用举报邮箱是什么? | L17: 是 | M17: kpwh@kaopuyun.com。 | N17: 员工道德规范准则.pdf /3.8 利益冲突原则 | O17: 员工利益冲突专用举报邮箱是：**kpwh@kaopuyun.com**（依据《员工道德规范准则》第3.8条）。 员工可将自己已实际发生或潜在的利益冲突及竞争行为直接发送至该邮箱，如实向公司 CEO 和 CFO 报告。 | P17: 员工道德规范准则.pdf:L17｜## 3. 利益冲突原则\n50477ce8-acfb-40a9-a8ad-c6ae467fa3ad 员工道德规范准则.pdf:28: 3.6.员工不得从事与 | Q17: http://192.168.151.14:3000/c/148a11f0-a345-428a-bdd0-16813496ec37 | R17: 是 | S17: 无明显异常 | T17: 5 | U17: 5 | V17: 5 | W17: 否 | X17: 否 | Y17: 通过
A18: L1-0011 | B18: RUN-L1-008 | C18: 2026-08-20 | D18: 测试人员A | E18: =IFERROR(VLOOKUP(B18,'90-测试批次配置'!$A$4:$P$200,10,FALSE),"") | F18: PDF/DOCX | G18: 反商业贿赂制度V1.0.pdf | H18: ≤2MB | I18: 直接事实 | J18: 中 | K18: 《反商业贿赂制度》当前版本号是什么?由谁批准? | L18: 是 | M18: 当前版本为V1.0,由柳明兴批准,黄肖审核,陈慧明修订。 | N18: 反商业贿赂制度V1.0.pdf /修订履历表 | O18: 《反商业贿赂制度》当前版本号为 **V1.0**（2025-4-1 新建制度），由**柳明兴**批准（修改者：陈慧明，审核者：黄肖）。 | P18: 反商业贿赂制度V1.0.pdf:L1,113｜## 反商业贿赂制度\n2c15d011-ed12-4d9e-9f72-4f857ede2dca 反商业贿赂制度V1.0.pdf:14: 3.1 公司员工应与 | Q18: http://192.168.151.14:3000/c/22ada5c2-54c7-46c0-afbd-d8574dc95afc | R18: 是 | S18: 表述与标准答案不同 | T18: 4 | U18: 5 | V18: 5 | W18: 否 | X18: 否 | Y18: 通过 | AB18: 引用命中但回答表述与标准答案不同，建议人工核查。标准答案：当前版本为V1.0,由柳明兴批准,黄肖审核,陈慧明修订。
A19: L1-0012 | B19: RUN-L1-008 | C19: 2026-08-20 | D19: 测试人员A | E19: =IFERROR(VLOOKUP(B19,'90-测试批次配置'!$A$4:$P$200,10,FALSE),"") | F19: PDF/DOCX | G19: 反商业贿赂制度V1.0.pdf | H19: ≤2MB | I19: 直接事实 | J19: 中 | K19: 员工违反反商业贿赂制度,公司有哪几种处理措施? | L19: 是 | M19: 共5种:1)口头警告;2)书面警告;3)罚款;4)解除劳动合同;5)移交司法机关。 | N19: 反商业贿赂制度V1.0.pdf /3.11.1~3.11.5 | O19: 根据《反商业贿赂制度V1.0》第3.11条，员工违反本制度的，公司将根据行为的性质、情节轻重及造成的后果，采取以下一种或多种处理措施 [1]： 1. **口头警告**：情节轻微、未造成实际损失的，给予口头警告，并要求立即改正 [1]。 2. **书面警告**：情节较重但未造成重大损失的，给予书面警告，并记录在个人档案中 [1]。 3. **罚款**：情节严重、造成一定经济损失的，根据损失程度进行罚款 [1]。 4. **解除劳动合同**：严重违反制度、造成重大损失或恶劣影响，或屡教不改的，解除劳动合同 [1]。 5. **移交司法机关**：构成犯罪的商业贿赂行为，移交司法机关依法追究刑事责任 [1]。 | P19: 反商业贿赂制度V1.0.pdf:L1｜## 反商业贿赂制度\n2c15d011-ed12-4d9e-9f72-4f857ede2dca 反商业贿赂制度V1.0.pdf:5: 为扎实推进商业活动的反 | Q19: http://192.168.151.14:3000/c/5a59a8cf-bf2e-4740-a631-6d6a34cecc21 | R19: 是 | S19: 无明显异常 | T19: 5 | U19: 5 | V19: 5 | W19: 否 | X19: 否 | Y19: 通过
A20: L1-0013 | B20: RUN-L1-008 | C20: 2026-08-20 | D20: 测试人员A | E20: =IFERROR(VLOOKUP(B20,'90-测试批次配置'!$A$4:$P$200,10,FALSE),"") | F20: PDF/DOCX | G20: 反商业贿赂制度V1.0.pdf | H20: ≤2MB | I20: 直接事实 | J20: 中 | K20: 《反商业贿赂承诺书》何时生效?何时失效? | L20: 是 | M20: 自签字盖章之日起生效,自劳动合同解除时自动失效。离职后若在职期间存在商业贿赂行为,公司保留追溯权,承诺书失效不影响已发生行为的追责。 | N20: 反商业贿赂制度V1.0.pdf /3.1 / 3.2 | O20: 根据《反商业贿赂制度V1.0》第3.1条规定： - **生效时间**：《反商业贿赂承诺书(员工版)》自**签字盖章之日起生效**。 - **失效时间**：自**劳动合同解除时自动失效**。 | P20: 反商业贿赂制度V1.0.pdf:L14｜3.1 公司员工应与公司签订《反商业贿赂承诺书(员工版)》,此承诺书自签字盖章之日起生效,自劳动合同解除时自动失效。 \n2c15d011-ed12-4d9e | Q20: http://192.168.151.14:3000/c/0632dfe3-c3da-45e6-a4ce-c0e3e04d8cc8 | R20: 是 | S20: 表述与标准答案不同 | T20: 4 | U20: 5 | V20: 5 | W20: 否 | X20: 否 | Y20: 通过 | AB20: 引用命中但回答表述与标准答案不同，建议人工核查。标准答案：自签字盖章之日起生效,自劳动合同解除时自动失效。离职后若在职期间存在商业贿赂行为,公司保留追溯权,承
A21: L1-0014 | B21: RUN-L1-008 | C21: 2026-08-20 | D21: 测试人员A | E21: =IFERROR(VLOOKUP(B21,'90-测试批次配置'!$A$4:$P$200,10,FALSE),"") | F21: PDF/DOCX | G21: 反商业贿赂制度V1.0.pdf | H21: ≤2MB | I21: 直接事实 | J21: 难 | K21: 国际业务反商业贿赂管理中,公司须遵守哪些国际法律法规? | L21: 是 | M21: 须严格遵守业务所在国家/地区的反商业贿赂法律法规,包括但不限于:美国《反海外腐败法》(FCPA)、英国《贿赂法案》(Bribery Act)、经济合作与发展组织(OECD)《反贿赂公约》、联合国《反腐败公约》等。 | N21: 反商业贿赂制度V1.0.pdf /3.7 | O21: 根据《反商业贿赂制度V1.0》第3.7条，公司及员工在开展国际业务时，须严格遵守业务所在国家/地区的反商业贿赂法律法规，包括但不限于 [1]： - 美国《反海外腐败法》（FCPA）； - 英国《贿赂法案》（Bribery Act）； - 经济合作与发展组织（OECD）《反贿赂公约》； - 联合国《反腐败公约》等。 此外，制度还明确禁止通过直接或间接方式（如通过第三方中介）向外国公职人员、商业伙伴提供不正当利益以谋取商业优势 [1]。 | P21: 反商业贿赂制度V1.0.pdf:L1｜## 反商业贿赂制度\n2c15d011-ed12-4d9e-9f72-4f857ede2dca 反商业贿赂制度V1.0.pdf:14: 3.1 公司员工应与 | Q21: http://192.168.151.14:3000/c/e166e790-fb1e-41ab-a4be-08ced3356d2c | R21: 是 | S21: 无明显异常 | T21: 5 | U21: 5 | V21: 5 | W21: 否 | X21: 否 | Y21: 通过
A22: L1-0015 | B22: RUN-L1-008 | C22: 2026-08-20 | D22: 测试人员A | E22: =IFERROR(VLOOKUP(B22,'90-测试批次配置'!$A$4:$P$200,10,FALSE),"") | F22: PDF/DOCX | G22: 员工道德规范准则.pdf | H22: ≤2MB | I22: 直接事实 | J22: 易 | K22: 公司对外信息披露由哪个部门归口负责? | L22: 是 | M22: 由董秘办归口负责,按照规定的信息披露办法、方式、内容和标准进行披露。 | N22: 员工道德规范准则.pdf /5.1 信息披露 | O22: 根据《员工道德规范准则》第5.1条规定： **公司对外的信息披露由董秘办（董事会秘书办公室）归口负责**，按照规定的信息披露办法、方式、内容和标准，真实、完整、准确、及时地披露企业生产经营和管理情况相关的信息。 同时请注意第5.2条：未经公司信息披露主管部门许可，任何人不得擅自对外公开披露或发表尚未公开的公司信息，也不得擅自以公司员工身份或以公司名义对外发表与公司有关的个人评论与看法。 | P22: 员工道德规范准则.pdf:L56｜## 5. 信息披露\n50477ce8-acfb-40a9-a8ad-c6ae467fa3ad 员工道德规范准则.pdf:58: 5.1.公司对外的信息披露 | Q22: http://192.168.151.14:3000/c/4d91cb86-a21b-4dae-834a-abaa5a3d4eb8 | R22: 是 | S22: 无明显异常 | T22: 5 | U22: 5 | V22: 5 | W22: 否 | X22: 否 | Y22: 通过
A23: L1-0016 | B23: RUN-L1-008 | C23: 2026-08-20 | D23: 测试人员A | E23: =IFERROR(VLOOKUP(B23,'90-测试批次配置'!$A$4:$P$200,10,FALSE),"") | F23: PDF/DOCX | G23: 反商业贿赂制度V1.0.pdf | H23: ≤2MB | I23: 直接事实 | J23: 易 | K23: 反商业贿赂监督管理小组由哪个部门组成? | L23: 是 | M23: 由总经办组成预防商业贿赂承诺制的监督管理小组。 | N23: 反商业贿赂制度V1.0.pdf /3.3 | O23: 根据《反商业贿赂制度V1.0》第3.3条规定：公司的反商业贿赂（预防商业贿赂承诺制）**监督管理小组由总经办组成**，负责对商业贿赂预防工作进行监督管理。 | P23: 反商业贿赂制度V1.0.pdf:L1,16｜## 反商业贿赂制度\n2c15d011-ed12-4d9e-9f72-4f857ede2dca 反商业贿赂制度V1.0.pdf:14: 3.1 公司员工应与 | Q23: http://192.168.151.14:3000/c/651bec59-88bb-44a4-a3de-8c11911423c3 | R23: 是 | S23: 无明显异常 | T23: 5 | U23: 5 | V23: 5 | W23: 否 | X23: 否 | Y23: 通过
A24: L1-0017 | B24: RUN-L1-008 | C24: 2026-08-20 | D24: 测试人员A | E24: =IFERROR(VLOOKUP(B24,'90-测试批次配置'!$A$4:$P$200,10,FALSE),"") | F24: PDF/DOCX | G24: 员工道德规范准则.pdf | H24: ≤2MB | I24: 直接事实 | J24: 中 | K24: 员工保密义务在离职后是否继续有效? | L24: 是 | M24: 员工保密义务在其离职后的一定期限内仍然有效,义务持续期应根据公平的原则结合具体情况由公司决定。 | N24: 员工道德规范准则.pdf /4.8 保密义务 | O24: 是的,继续有效。根据《员工道德规范准则》第4.8条规定:员工的保密义务在其离职后的一定期限内仍然有效,义务持续期应根据公平的原则结合具体情况由公司决定 [1]。 也就是说,离职并不解除保密义务,但离职后的保密义务并非无限期,而是持续一段由公司结合公平原则和具体情况确定的期限。此外,若在职期间泄露公司机密给公司造成损失,公司还可依第4.6条要求赔偿并追究相应责任 [1]。 | P24: 反商业贿赂制度V1.0.pdf:L15｜3.2 员工离职后,若在职期间存在商业贿赂行为,公司保留追溯权,承诺书失效不影响已发生行为的追责。 \n50477ce8-acfb-40a9-a8ad-c6a | Q24: http://192.168.151.14:3000/c/34cd9f17-8ea1-4733-bee2-b930501d6b83 | R24: 是 | S24: 引用命中文档与期望不符 | T24: 5 | U24: 5 | V24: 4 | W24: 否 | X24: 否 | Y24: 通过 | AB24: 引用命中：['反商业贿赂制度V1.0.pdf']，期望来源：员工道德规范准则.pdf，疑似知识库内容重叠或检索偏差，建议人工核查
A25: L1-0018 | B25: RUN-L1-008 | C25: 2026-08-20 | D25: 测试人员A | E25: =IFERROR(VLOOKUP(B25,'90-测试批次配置'!$A$4:$P$200,10,FALSE),"") | F25: PDF/DOCX | G25: 员工道德规范准则.pdf | H25: ≤2MB | I25: 直接事实 | J25: 易 | K25: 员工道德规范准则中,哪些行为属于'爱国守法'的要求? | L25: 是 | M25: 1)所有员工必须遵守中华人民共和国的法律、法规;2)不在任何场合、以任何形式发表诋毁国家的言论;3)不得参加带有邪教性质的组织。 | N25: 员工道德规范准则.pdf /2.1~2.3 爱国守法 | O25: 根据《员工道德规范准则》第2条，“爱国守法”包含以下三项要求： 1. **遵守法律法规**：所有员工必须遵守中华人民共和国的法律、法规（2.1）。 2. **不发表不当言论**：不在任何场合、以任何形式发表诋毁国家的言论（2.2）。 3. **不参加邪教组织**：不得参加带有邪教性质的组织（2.3）。 | P25: 员工道德规范准则.pdf:L1,11｜## 2. 爱国守法'}] | Q25: http://192.168.151.14:3000/c/91bd800e-a519-444a-accf-68bf6e26d4e1 | R25: 是 | S25: 无明显异常 | T25: 5 | U25: 5 | V25: 5 | W25: 否 | X25: 否 | Y25: 通过
A26: L1-0019 | B26: RUN-L1-008 | C26: 2026-08-20 | D26: 测试人员A | E26: =IFERROR(VLOOKUP(B26,'90-测试批次配置'!$A$4:$P$200,10,FALSE),"") | F26: PDF/DOCX | G26: 员工道德规范准则.pdf | H26: ≤2MB | I26: 多轮对话 | J26: 中 | K26: 供应商在中秋节给我寄了一盒月饼,我收下应该没事吧? | L26: 是 | M26: 不可以收下。员工道德规范准则3.1条规定不得接受与公司有业务往来的或正在寻求与公司进行交易的组织/个人提供的报酬、馈赠、金钱、贷款、服务、礼品等,月饼属于馈赠/礼品范畴。 | N26: 员工道德规范准则.pdf /3.1 利益冲突原则 | O26: **不建议收下，直接收下是有问题的。** 根据《员工道德规范准则》第3.1条规定：不得接受与公司有业务往来的或正在寻求与公司进行交易的组织/个人提供的报酬、馈赠、金钱、贷款、服务、礼品等，也不得安排亲属、朋友接受上述利益 [1]。 供应商属于"与公司有业务往来的组织"，中秋月饼属于典型的节日礼品/馈赠，因此收下即违反上述规定。此外，您也不能让家人、朋友代为收下，这同样在禁止之列 [1]。 **建议的处理方式：** 1. 礼貌婉拒，向供应商说明公司的廉洁规定； 2. 如对方已寄出、无法退回，应按照准则第3.8条的要求，及时向直接主管报告，或向公司 CEO、CFO 报告（专用邮箱：kpwh@kaopuyun.com），并交由公司统一处理（如上交或退回）[1]。 简言之：能退则退，不能退则及时如实报告，切勿私自收下食用。 | P26: 员工道德规范准则.pdf:L19｜3.1.不得接受竞争对手、与公司有业务往来的或正在寻求与公司进行交易的组织/个人提供的报酬、馈赠、金钱、贷款、服务、礼品等,也不得安排其亲属、朋友接受上述利益。; 反商业贿赂制度V1.0.pdf:L60｜3.13 公司设立举报奖励机制,对提供真实有效举报信息且经查证属实的举报人给予奖励。根据举报内容的价值和贡献,奖励金额为500元至5万元,或按挽回损失的5%计算 | Q26: http://192.168.151.14:3000/c/3f29c989-4214-4be8-8a23-c0f079f1809e | R26: 是 | S26: 无明显异常 | T26: 5 | U26: 5 | V26: 5 | W26: 否 | X26: 否 | Y26: 通过 | AB26: 多轮对话第M01组·轮次首问
A27: L1-0020 | B27: RUN-L1-008 | C27: 2026-08-20 | D27: 测试人员A | E27: =IFERROR(VLOOKUP(B27,'90-测试批次配置'!$A$4:$P$200,10,FALSE),"") | F27: PDF/DOCX | G27: 员工道德规范准则.pdf | H27: ≤2MB | I27: 多轮对话 | J27: 中 | K27: (追问)那如果是客户送的呢?客户不是供应商,应该可以吧? | L27: 是 | M27: 同样不可以。3.1条明确覆盖了'竞争对手、与公司有业务往来的或正在寻求与公司进行交易的组织/个人'三类主体,客户属于'与公司有业务往来的组织',同样在禁止范围内。也不得安排其亲属、朋友接受上述利益。 | N27: 员工道德规范准则.pdf /3.1 利益冲突原则 | O27: **客户送的也不可以。** 《员工道德规范准则》第3.1条禁止的范围不只是供应商，而是"竞争对手、**与公司有业务往来的**或正在寻求与公司进行交易的组织/个人" [1]。客户显然与公司存在业务往来，属于明令禁止的对象之一。 也就是说，无论是供应商、客户、合作伙伴，还是潜在客户，只要与公司有或可能有业务关系，其提供的礼品、馈赠、报酬等都不能收 [1]。 **建议处理方式同前：** - 能拒收就礼貌婉拒，说明公司规定； - 已寄出无法退回的，按第3.8条及时向直接主管或公司 CEO、CFO 报告（kpwh@kaopuyun.com），由公司统一处理 [1]。 如果拿不准某种情况是否构成利益冲突，准则也要求及时向直接主管或 CEO/CFO 询问确认，不要自行判断后默默收下 [1]。 | P27: 未引用（无工具命中） | Q27: http://192.168.151.14:3000/c/3f29c989-4214-4be8-8a23-c0f079f1809e | R27: 是 | S27: 引用命中文档与期望不符 | T27: 4 | U27: 5 | V27: 4 | W27: 否 | X27: 否 | Y27: 通过 | AB27: 引用命中：[]，期望来源：员工道德规范准则.pdf，疑似知识库内容重叠或检索偏差，建议人工核查；多轮对话第M01组·轮次追问
A28: L1-0021 | B28: RUN-L1-008 | C28: 2026-08-20 | D28: 测试人员A | E28: =IFERROR(VLOOKUP(B28,'90-测试批次配置'!$A$4:$P$200,10,FALSE),"") | F28: PDF/DOCX | G28: 员工道德规范准则.pdf | H28: ≤2MB | I28: 多轮对话 | J28: 中 | K28: (追问)那如果只是一张贺卡呢?价值很小,也算违规吗? | L28: 是 | M28: 仍属于被禁止的范围。3.1条未设置金额门槛,任何来自有业务往来组织/个人的报酬、馈赠、金钱、贷款、服务、礼品等均在禁止之列。如确属象征性的贺卡且不便退回,建议向直接主管或法务部报告并按公司指导处理,不应私自留存。 | N28: 员工道德规范准则.pdf /3.1 / 3.8 | O28: **根据公司制度，贺卡同样属于"馈赠、礼品"，严格来说也在禁止范围内，制度中并没有按金额大小设豁免。** 需要说明的是，《反商业贿赂制度》中并没有针对小额礼品（如贺卡）设置价值豁免条款 [1]。该制度要求员工"禁止任何形式的商业贿赂行为" [1]，违反时公司将根据行为的性质、情节轻重及后果分级处理——情节轻微、未造成实际损失的，仅给予口头警告并要求立即改正 [1]。 结合《员工道德规范准则》第3.1条，馈赠、礼品均在不得接受之列，并未区分价值高低。 **实务建议：** - 单纯的节日贺卡（无现金、无购物卡等附加利益）通常被视为正常商务礼节，一般不构成商业贿赂，风险极低；即使被认定违规，按制度也仅属于"情节轻微"的口头警告级别 [1]。 - 但请注意贺卡内是否夹带购物卡、礼金等——那就完全是另一回事了。 - 如果仍有疑虑，最稳妥的做法是向直接主管或公司反商业贿赂管理小组咨询确认（电话 18950299832，邮箱 Fanhl@kaopucloud.com）[1]。 | P28: 反商业贿赂制度V1.0.pdf:L60｜3.13 公司设立举报奖励机制,对提供真实有效举报信息且经查证属实的举报人给予奖励。根据举报内容的价值和贡献,奖励金额为500元至5万元,或按挽回损失的5%计算 | Q28: http://192.168.151.14:3000/c/3f29c989-4214-4be8-8a23-c0f079f1809e | R28: 是 | S28: 引用命中文档与期望不符 | T28: 4 | U28: 5 | V28: 4 | W28: 否 | X28: 否 | Y28: 通过 | AB28: 引用命中：['反商业贿赂制度V1.0.pdf']，期望来源：员工道德规范准则.pdf，疑似知识库内容重叠或检索偏差，建议人工核查；多轮对话第M01组·轮次追问
A29: L1-0022 | B29: RUN-L1-008 | C29: 2026-08-20 | D29: 测试人员A | E29: =IFERROR(VLOOKUP(B29,'90-测试批次配置'!$A$4:$P$200,10,FALSE),"") | F29: PDF/DOCX | G29: 员工道德规范准则.pdf | H29: ≤2MB | I29: 多轮对话 | J29: 难 | K29: 我想离职后去竞品公司上班,公司能管我吗? | L29: 是 | M29: 需视情况而定。3.6条规定员工不得从事与公司存在或潜在的利益冲突和竞争行为。在职期间,员工及主要近亲属不得自营或为他人经营与公司直接或间接竞争的任何业务。离职后的保密义务在一定期限内仍有效(4.8条),但文档未明确禁止离职后入职竞品公司,具体以劳动合同和竞业限制协议约定为准。 | N29: 员工道德规范准则.pdf /3.6 / 4.8 | O29: **简要回答：可以管，但要区分情况。** 根据公司制度文件，主要看两点： **1️⃣ 在职期间 —— 明确禁止** 《员工道德规范准则》3.6 条规定，员工不得从事与公司存在或潜在利益冲突和竞争行为，具体包括： - 自营或为他人经营、参与经营与公司直接或间接竞争的任何业务； - 与公司构成竞争关系的组织/个人存在聘任或劳务关系。 所以**离职前**不能一边在职、一边去竞品任职或为竞品做事，这属于明确违规。 **2️⃣ 离职之后 —— 保密义务延续** 准则 4.8 条规定：员工的保密义务在离职后一定期限内仍然有效，持续期由公司结合具体情况决定。 也就是说： - ❌ 离职后**不能**将公司的商业秘密、客户信息、技术资料等带去或用于竞品公司； - ✅ 但单纯的"去竞品公司上班"本身，是否受限要看是否签有**竞业限制协议/条款**及公司是否支付竞业补偿金——这是劳动合同法层面的问题，公司制度文件本身未设定普遍的离职竞业禁止。 **建议：** 1. 查看你签署的劳动合同中是否有竞业限制条款及补偿约定； 2. 如不确定，按准则 3.8 条向直接主管或公司法务部咨询/报告（或发邮件至 kpwh@kaopuyun.com）； 3. 无论去哪家公司，务必严格保守公司商业秘密，否则离职后仍可能被追责。 | P29: 员工道德规范准则.pdf:L19｜3.1.不得接受竞争对手、与公司有业务往来的或正在寻求与公司进行交易的组织/个人提供的报酬、馈赠、金钱、贷款、服务、礼品等,也不得安排其亲属、朋友接受上述利益。; 反商业贿赂制度V1.0.pdf:L5｜为扎实推进商业活动的反腐败和反贿赂工作,加强企业内控机制,做到诚实守信,树立以守法诚信、优质服务为核心的经营理念,结合公司的实际情况,强化制度监督,推进制度反腐 | Q29: http://192.168.151.14:3000/c/a0da2cf0-15e4-4f2f-88b0-5974260a7147 | R29: 是 | S29: 无明显异常 | T29: 5 | U29: 5 | V29: 5 | W29: 否 | X29: 否 | Y29: 通过 | AB29: 多轮对话第M02组·轮次首问
A30: L1-0023 | B30: RUN-L1-008 | C30: 2026-08-20 | D30: 测试人员A | E30: =IFERROR(VLOOKUP(B30,'90-测试批次配置'!$A$4:$P$200,10,FALSE),"") | F30: PDF/DOCX | G30: 员工道德规范准则.pdf | H30: ≤2MB | I30: 多轮对话 | J30: 中 | K30: (追问)那如果我弟弟开了一家和我们公司一样的公司,我在职期间能去帮忙吗? | L30: 是 | M30: 不可以。3.6条明确规定员工(包括董事和高管)和/或其主要近亲属自营或者为他人经营、参与经营与公司直接或间接竞争的任何业务,属于利益冲突和竞争行为,不得从事。弟弟属于主要近亲属范畴。 | N30: 员工道德规范准则.pdf /3.6 利益冲突原则 | O30: **简要回答：不能，这属于明确禁止的利益冲突和竞争行为。** 弟弟属于“主要近亲属”，根据《员工道德规范准则》： **1️⃣ 这属于被禁止的竞争行为** 准则 3.6 条规定，员工不得从事与公司存在或潜在利益冲突和竞争行为，具体情形包括： - 员工和/或其**主要近亲属**自营或为他人经营、参与经营与公司直接或间接竞争的任何业务 [1]； - 员工与公司构成竞争关系的组织存在聘任关系或**劳务关系或活动** [1]。 你弟弟开的公司与公司业务相同（构成直接竞争），你去“帮忙”即属于参与经营竞争业务，同时构成与竞争组织的劳务/活动关系，双重违规。 **2️⃣ 补充注意** - 如果涉及经济利益，还可能触发 3.5 条关于利益关系（如实质性财务利益）的限制 [1]； - 即使“只是偶尔帮忙”、不拿报酬，只要客观上参与经营了竞争业务，仍在禁止范围内。 **3️⃣ 正确做法** 按照准则 3.8 条，当你不确定行为是否与公司利益存在冲突或竞争时，应**及时向直接主管提出询问，或直接向公司 CEO 和 CFO 报告**，也可向法务部报告，由其审查并作出决定 [1]。专用报告邮箱：kpwh@kaopuyun.com [1]。 **建议**：在职期间不要参与弟弟公司的任何经营活动；如已参与或有其他关联往来，应主动如实报告，避免被认定为隐瞒利益冲突。 | P30: 未引用（无工具命中） | Q30: http://192.168.151.14:3000/c/a0da2cf0-15e4-4f2f-88b0-5974260a7147 | R30: 是 | S30: 引用命中文档与期望不符 | T30: 5 | U30: 5 | V30: 4 | W30: 否 | X30: 否 | Y30: 通过 | AB30: 引用命中：[]，期望来源：员工道德规范准则.pdf，疑似知识库内容重叠或检索偏差，建议人工核查；多轮对话第M02组·轮次追问
A31: L1-0024 | B31: RUN-L1-008 | C31: 2026-08-20 | D31: 测试人员A | E31: =IFERROR(VLOOKUP(B31,'90-测试批次配置'!$A$4:$P$200,10,FALSE),"") | F31: PDF/DOCX | G31: 员工道德规范准则.pdf；反商业贿赂制度V1.0.pdf | H31: ≤2MB | I31: 多轮对话 | J31: 中 | K31: (追问)那我离职之后呢?保密义务还有效吗? | L31: 是 | M31: 保密义务仍然有效。4.8条规定员工保密义务在离职后的一定期限内仍然有效,义务持续期根据公平原则结合具体情况由公司决定。此外,《反商业贿赂承诺书》虽在劳动合同解除时自动失效,但离职后若在职期间存在商业贿赂行为,公司保留追溯权(3.2条)。 | N31: 员工道德规范准则.pdf；反商业贿赂制度V1.0.pdf /DOC2 4.8 / DOC1 3.2 | O31: **简要回答：保密义务在离职后仍然有效，但不是无限的。** 根据《员工道德规范准则》4.8 条：员工的保密义务在其离职后的一定期限内仍然有效，**义务持续期应根据公平原则、结合具体情况由公司决定** [1]。 结合准则第四章其他条款，离职后仍然需要遵守的包括： **1️⃣ 离职后仍有效的保密义务** - 不得泄露在职期间获悉的公司经营状况、业务数据、文件资料（4.1、4.2 条）[1]； - 对公司客户或潜在客户的保密信息继续保密（4.3 条）[1]； - 因泄密给公司造成损失的，公司有权要求赔偿损失，并追究法律责任（4.6 条）[1]。 **2️⃣ 离职后不受约束的部分** - 单纯的去向选择（去竞品公司上班）——除非签有竞业限制协议且有补偿安排，否则制度本身不设定普遍的离职竞业禁止（如前述）； - 已进入公有领域、不构成商业秘密的一般知识、技能和经验。 **3️⃣ 实务提醒** - 保密义务的持续期由公司"决定"在法律上以**合理的商业秘密保护期**为限——只要信息仍构成商业秘密，保密义务就一直存在，与是否在职无关； - 反商业贿赂制度 3.2 条也规定，员工离职后，在职期间若存在商业贿赂行为，公司保留追溯权 [2]——即在职期间的行为责任不因离职而免除。 **总结**：离职 ≠ 义务终结。商业秘密和客户保密信息不能带走、不能用；如对具体保密范围和期限有疑问，建议离职时与公司法务部确认交接清单，避免后续纠纷。 | P31: 未引用（无工具命中） | Q31: http://192.168.151.14:3000/c/a0da2cf0-15e4-4f2f-88b0-5974260a7147 | R31: 是 | S31: 引用命中文档与期望不符 | T31: 5 | U31: 5 | V31: 4 | W31: 否 | X31: 否 | Y31: 通过 | AB31: 引用命中：[]，期望来源：员工道德规范准则.pdf反商业贿赂制度V1.0.pdf，疑似知识库内容重叠或检索偏差，建议人工核查；多轮对话第M02组·轮次追问
A32: L1-0025 | B32: RUN-L1-008 | C32: 2026-08-20 | D32: 测试人员A | E32: =IFERROR(VLOOKUP(B32,'90-测试批次配置'!$A$4:$P$200,10,FALSE),"") | F32: PDF/DOCX | G32: 反商业贿赂制度V1.0.pdf | H32: ≤2MB | I32: 多轮对话 | J32: 中 | K32: 我想举报同事收了供应商的红包,但不想让他知道是我举报的,有办法吗? | L32: 是 | M32: 有。3.12条规定检举的受理、调查等各环节必须严格保密,严禁泄露检举人的姓名、部门、公司名称等信息,严禁将举报情况透露给被举报人或部门。你可以通过电话18950299832或邮箱Fanhl@kaopuycloud.com联系反商业贿赂管理小组进行举报,公司会严格保密你的身份。 | N32: 反商业贿赂制度V1.0.pdf /3.12 / 3.14 | O32: 有办法。根据公司《反商业贿赂制度 V1.0》和《员工道德规范准则》，你可以放心举报，且你的身份会受保护： ## 制度依据 **你同事的行为已违规：** - 《员工道德规范准则》3.1：员工不得接受与公司有业务往来的组织/个人提供的报酬、馈赠、金钱、礼品等利益（也不得安排亲属朋友接受）。 - 收供应商红包属于商业贿赂行为，违反《反商业贿赂制度》。 **举报人保护机制（制度 3.12、3.13）：** - 公司鼓励员工检举揭发腐败行为； - 受理、调查各环节**严格保密**，严禁泄露举报人姓名、部门等信息； - 严禁将举报情况透露给被举报人或部门；调查时不得出示举报材料原件/复印件，不得暴露举报人； - **支持匿名举报**——匿名检举材料不得鉴定笔迹； - **禁止任何形式的打击报复**，违者追究责任； - 查证属实还有举报奖励（500 元至 5 万元，或按挽回损失的 5%）。 ## 建议操作方式 1. **选择匿名举报**：制度明确支持匿名检举且受同等保护，这是最彻底的保密方式； 2. **提供客观证据**：无论实名还是匿名，尽量附上时间、供应商名称、金额、转账/聊天记录等线索，便于查证（查证属实才有奖励，也更易被采信）； 3. **避免先向本部门负责人反映**：以防信息在你不知情时传回被举报人； 4. **注意举报后的言行**：不要向同事透露你知情或关注此事，避免因言论推测暴露身份。 如果你想匿名但担心线索太具体会被猜到，可以只提供关键事实（如涉及哪位供应商、大致时间），让公司自行调查取证。 | P32: 反商业贿赂制度V1.0.pdf:L5,59｜3.12 公司鼓励员工及与公司有业务往来的公司检举揭发腐败行为,检举的受理、调查等各个环节,必须严格保密,严禁泄露检举人的姓名、部门、公司名称等信息,严禁将举报 | Q32: http://192.168.151.14:3000/c/f9edca4d-59ed-45cb-94e8-96ab658781b5 | R32: 是 | S32: 表述与标准答案不同 | T32: 4 | U32: 5 | V32: 5 | W32: 否 | X32: 否 | Y32: 通过 | AB32: 引用命中但回答表述与标准答案不同，建议人工核查。标准答案：有。3.12条规定检举的受理、调查等各环节必须严格保密,严禁泄露检举人的姓名、部门、公司名称等信息,；多轮对话第M03组·轮次首问
A33: L1-0026 | B33: RUN-L1-008 | C33: 2026-08-20 | D33: 测试人员A | E33: =IFERROR(VLOOKUP(B33,'90-测试批次配置'!$A$4:$P$200,10,FALSE),"") | F33: PDF/DOCX | G33: 反商业贿赂制度V1.0.pdf | H33: ≤2MB | I33: 多轮对话 | J33: 中 | K33: (追问)那万一举报之后同事知道了是我举报的,故意找茬报复怎么办? | L33: 是 | M33: 3.13条明确规定公司对举报人信息严格保密,禁止任何形式的打击报复,违者将追究责任。如果发生打击报复行为,你可以再次向反商业贿赂管理小组举报,公司将对报复者追究责任。此外,3.12条还规定匿名检举不得鉴定笔迹,检举材料不得随意对外借阅,层层保护举报人。 | N33: 反商业贿赂制度V1.0.pdf /3.12 / 3.13 | O33: 制度对这种情况是有明确约束的，同时你也可以做一些自我保护准备： ## 制度层面的保护 1. **明令禁止报复**（制度 3.13）：公司对举报人信息严格保密，**禁止任何形式的打击报复，违者将追究责任**。 2. **调查环节保密**（制度 3.12）：严禁泄露举报人姓名、部门，严禁将举报情况透露给被举报人或部门；调查核实时不得出示举报材料原件/复印件、不得暴露举报人；匿名材料不得鉴定笔迹。也就是说，按制度正常情况下对方**无从得知**是你举报的。 3. **报复行为本身可被追责**：如果对方故意刁难、排挤你，这属于违规违纪行为，按制度可以被处理（3.11 规定了从警告直至解除劳动合同的处分梯度；情节严重的报纪检监察部门或司法机关查处）。收红包行为一旦查实，对方自身还面临处分甚至解约、法律追究——一个自身已被查处的员工，报复的成本和风险都很高。 ## 你可以做的自我保护 1. **优先选择匿名举报**——这是最根本的防暴露手段； 2. **控制知情范围**：只向受理部门（而非部门负责人、同事）反映，不在职场议论此事； 3. **留证据**：如事后察觉对方针对性刁难（无理由调岗、绩效打压、言语威胁等），及时保存聊天记录、邮件、录音等证据； 4. **立即二次举报**：若遭遇报复，向受理部门再次反映“疑似因举报遭打击报复”，由公司启动追责； 5. **必要时寻求外部途径**：如公司处理不力或报复严重（如威胁人身安全），可向劳动监察部门投诉或报警。 简单说：制度不允许、也不敢轻易让被举报人知道举报人是谁；即便万一泄露，报复行为本身会被追究，且你手里有证据、有申诉渠道，并非孤立无援。 | P33: 反商业贿赂制度V1.0.pdf:L14,60｜3.13 公司设立举报奖励机制,对提供真实有效举报信息且经查证属实的举报人给予奖励。根据举报内容的价值和贡献,奖励金额为500元至5万元,或按挽回损失的5%计算 | Q33: http://192.168.151.14:3000/c/f9edca4d-59ed-45cb-94e8-96ab658781b5 | R33: 是 | S33: 表述与标准答案不同 | T33: 4 | U33: 5 | V33: 5 | W33: 否 | X33: 否 | Y33: 通过 | AB33: 引用命中但回答表述与标准答案不同，建议人工核查。标准答案：3.13条明确规定公司对举报人信息严格保密,禁止任何形式的打击报复,违者将追究责任。如果发生打击报复；多轮对话第M03组·轮次追问
A34: L1-0027 | B34: RUN-L1-008 | C34: 2026-08-20 | D34: 测试人员A | E34: =IFERROR(VLOOKUP(B34,'90-测试批次配置'!$A$4:$P$200,10,FALSE),"") | F34: PDF/DOCX | G34: 反商业贿赂制度V1.0.pdf | H34: ≤2MB | I34: 多轮对话 | J34: 中 | K34: (追问)那举报属实的话,我能拿到什么奖励吗? | L34: 是 | M34: 可以。3.13条规定公司设立举报奖励机制,对提供真实有效举报信息且经查证属实的举报人给予奖励。奖励金额为500元至5万元,或按挽回损失的5%计算,最高不超过5万元。根据举报内容的价值和贡献确定具体金额。 | N34: 反商业贿赂制度V1.0.pdf /3.13 | O34: 可以。根据《反商业贿赂制度 V1.0》第 3.13 条，公司设立了明确的举报奖励机制： ## 奖励标准 - **基础区间**：500 元至 5 万元，根据举报内容的**价值和贡献**确定； - **损失挂钩**：或按**挽回损失的 5%** 计算； - **上限**：最高不超过 **5 万元**。 ## 拿到奖励的条件 1. 举报信息**真实有效**； 2. **经查证属实**——所以前面建议你尽量提供具体线索（时间、供应商、金额、记录等）很重要，线索越扎实，越容易查实，奖励认定也越有利。 ## 需要注意 - 制度同时规定对举报人信息严格保密并禁止打击报复，领取奖励的流程一般也会通过受理部门保密处理，不会公开身份； - 具体发放方式（是否匿名领取、发放时间等）建议在举报时直接向受理部门咨询确认。 也就是说，你举报不仅是履行员工职责（公司鼓励检举腐败行为），查实后还有实实在在的奖金回报。 | P34: 未引用（无工具命中） | Q34: http://192.168.151.14:3000/c/f9edca4d-59ed-45cb-94e8-96ab658781b5 | R34: 是 | S34: 引用命中文档与期望不符 | T34: 5 | U34: 5 | V34: 4 | W34: 否 | X34: 否 | Y34: 通过 | AB34: 引用命中：[]，期望来源：反商业贿赂制度V1.0.pdf，疑似知识库内容重叠或检索偏差，建议人工核查；多轮对话第M03组·轮次追问
A35: L1-0028 | B35: RUN-L1-008 | C35: 2026-08-20 | D35: 测试人员A | E35: =IFERROR(VLOOKUP(B35,'90-测试批次配置'!$A$4:$P$200,10,FALSE),"") | F35: PDF/DOCX | G35: 无 | H35: ≤2MB | I35: 无答案问题 | J35: 易 | K35: 公司今年年终奖发多少?什么时候发? | L35: 否 | M35: 知识库中未涉及年终奖发放金额、时间等信息,无法回答。建议查阅《薪酬福利制度》或咨询人力资源部。 | N35: 无 /无 | O35: 我在已连接的知识库(《职业道德规范》)中搜索了"年终奖"相关内容,没有找到任何匹配信息——这个知识库只包含职业道德规范类内容,不涉及薪酬或公司政策。 关于年终奖的金额和发放时间,我无法提供准确答案。建议您: - 咨询公司人力资源部(HR) - 查看员工手册或劳动合同中的相关条款 - 关注公司内部公告 如果您有其他包含薪酬政策的文件,可以上传后我再帮您查询。 | P35: 未引用（无工具命中） | Q35: http://192.168.151.14:3000/c/91f6fd23-48c2-463f-bbdf-9660cabd9fb1 | R35: 正确拒答 | S35: 无明显异常 | T35: 5 | U35: 5 | V35: 5 | W35: 否 | X35: 否 | Y35: 通过 | AB35: 无答案题：模型正确识别知识库未涉及并拒答（含指引建议，未用自身知识作答）
A36: L1-0029 | B36: RUN-L1-008 | C36: 2026-08-20 | D36: 测试人员A | E36: =IFERROR(VLOOKUP(B36,'90-测试批次配置'!$A$4:$P$200,10,FALSE),"") | F36: PDF/DOCX | G36: 无 | H36: ≤2MB | I36: 无答案问题 | J36: 易 | K36: 公司规定的上下班时间是几点?周末要上班吗? | L36: 否 | M36: 知识库中未涉及考勤制度、上下班时间等信息,无法回答。建议查阅《行政制度介绍》或咨询人力资源部。 | N36: 无 /无 | O36: 很抱歉，根据现有的知识库内容，《员工道德规范准则》[1] 中并没有关于公司上下班时间和周末是否上班的规定。该文件主要涵盖的是爱国守法、利益冲突原则、保密义务、信息披露等职业道德方面的内容，不涉及考勤或工作时间安排。 建议您咨询公司人力资源部，或查阅公司的考勤管理制度等相关文件来了解具体的上下班时间安排。 | P36: 未引用（无工具命中） | Q36: http://192.168.151.14:3000/c/608018dc-70d1-4b8c-9957-f50a198ea900 | R36: 正确拒答 | S36: 无明显异常 | T36: 5 | U36: 5 | V36: 5 | W36: 否 | X36: 否 | Y36: 通过 | AB36: 无答案题：模型正确识别知识库未涉及并拒答（含指引建议，未用自身知识作答）
A37: L1-0030 | B37: RUN-L1-008 | C37: 2026-08-20 | D37: 测试人员A | E37: =IFERROR(VLOOKUP(B37,'90-测试批次配置'!$A$4:$P$200,10,FALSE),"") | F37: PDF/DOCX | G37: 无 | H37: ≤2MB | I37: 无答案问题 | J37: 易 | K37: 员工社保和公积金的缴纳比例分别是多少? | L37: 否 | M37: 知识库中未涉及社保、公积金缴纳比例等信息,无法回答。建议查阅《薪酬福利制度》或咨询人力资源部。 | N37: 无 /无 | O37: 很抱歉，我目前无法回答这个问题。 我检查了当前已挂载的知识库「职业道德规范」，其中只包含以下两个文件： 1. 《反商业贿赂制度V1.0.pdf》 2. 《员工道德规范准则.pdf》 这两个文件都是关于职业道德和反商业贿赂的内容，**没有涉及员工社保和公积金缴纳比例的相关信息**。 建议您： - 咨询公司人力资源部门获取准确的缴纳比例信息； - 如果公司有相关的人事制度或薪酬福利文件，可以将其上传到知识库中，我就能帮您查询了。 另外提醒一下，社保和公积金的缴纳比例通常因地区不同而有所差异，具体比例应以当地社保/公积金管理中心的政策为准。 | P37: 未引用（无工具命中） | Q37: http://192.168.151.14:3000/c/dae1d3c7-8f4a-4302-ab31-35bf82cea54f | R37: 正确拒答 | S37: 无明显异常 | T37: 5 | U37: 5 | V37: 5 | W37: 否 | X37: 否 | Y37: 通过 | AB37: 无答案题：模型正确识别知识库未涉及并拒答（含指引建议，未用自身知识作答）
... A40: L1-0033 | B40: RUN-L1-008 | C40: 2026-08-20 | D40: 测试人员A | E40: =IFERROR(VLOOKUP(B40,'90-测试批次配置'!$A$4:$P$200,10,FALSE),"") | F40: PDF/DOCX | G40: 员工道德规范准则.pdf | H40: ≤2MB | I40: 同义改写 | J40: 中 | K40: 同事帮了我个大忙,我请他吃顿饭表示感谢,这算不算贿赂? | L40: 是 | M40: 算。员工道德规范准则3.2条明确规定不得利用职务之便收受同事的贿赂,谋取个人私利。不论金额大小,利用职务之便的请客送礼均属于禁止行为。 | N40: 员工道德规范准则.pdf /3.2 利益冲突原则 | O40: **不算贿赂。** 根据公司的《反商业贿赂制度》和《员工道德规范准则》，您这种情况属于正常的同事人情往来，完全合规。 **判断的关键区别在于：** ✅ **正常人情往来（您的情况）** - 目的是表达感谢，基于私人情谊 - 发生在事后的、对方已经帮完忙 - 消费水平合理、符合日常同事聚餐标准 - 双方是平等的同事关系，不存在职务上的利益输送 ❌ **可能构成贿赂的情形** - 《员工道德规范准则》第3.2条明确："不得利用职务之便收受同事的贿赂，谋取个人私利" - 如果请客是为了让对方**利用职务便利**为您谋取不正当利益（如泄露信息、违规审批、篡改数据等），那就是贿赂 - 金额明显超出正常聚餐水平（如豪华宴请、附带贵重礼品） - 事前"许诺式"请客，暗示对方未来要"帮忙办事" **建议：** - 保持聚餐消费在普通水平即可 - 如果对方是采购、销售等敏感岗位，或帮忙事项涉及职务权限，建议格外注意场合和形式 总之，事后一顿普通的工作餐表达谢意，是健康的职场文化，不必担心。😊 | P40: 反商业贿赂制度V1.0.pdf:L1｜## 反商业贿赂制度\n2c15d011-ed12-4d9e-9f72-4f857ede2dca 反商业贿赂制度V1.0.pdf:5: 为扎实推进商业活动的反 | Q40: http://192.168.151.14:3000/c/dfe33e66-c385-4bcb-b3d3-5535c2c04e86 | R40: 是 | S40: 引用命中文档与期望不符 | T40: 5 | U40: 5 | V40: 4 | W40: 否 | X40: 否 | Y40: 通过 | AB40: 引用命中：['反商业贿赂制度V1.0.pdf']，期望来源：员工道德规范准则.pdf，疑似知识库内容重叠或检索偏差，建议人工核查
A41: L1-0034 | B41: RUN-L1-008 | C41: 2026-08-20 | D41: 测试人员A | E41: =IFERROR(VLOOKUP(B41,'90-测试批次配置'!$A$4:$P$200,10,FALSE),"") | F41: PDF/DOCX | G41: 员工道德规范准则.pdf | H41: ≤2MB | I41: 同义改写 | J41: 中 | K41: 我老婆想自己开一家和我们公司一样的公司,这行不行? | L41: 是 | M41: 不行。员工道德规范准则3.6条明确规定,员工(包括董事和高管)和/或其主要近亲属自营或者为他人经营、参与经营与公司直接或间接竞争的任何业务,属于利益冲突和竞争行为,不得从事。 | N41: 员工道德规范准则.pdf /3.6 利益冲突原则 | O41: **这个问题涉及利益冲突,按《员工道德规范准则》的规定,原则上是不行的,至少必须先向公司报告并获得处理。** 具体依据如下: 1. **属于明确列举的利益冲突情形**:准则第 3.6 条规定,员工"和/或其主要近亲属自营或者为他人经营、参与经营与公司直接或间接竞争的任何业务"属于利益冲突和竞争行为 [1]。您配偶(属于主要近亲属)开设与公司相同的公司,正好落入这一情形。 2. **需要提前报告**:准则第 3.8 条要求员工主动、及时就实际发生或潜在的利益冲突和竞争行为向公司 CEO 和 CFO 如实报告(可发送至专用邮箱 kpwh@kaopuyun.com),也可向直接主管报告;拿不准是否构成冲突时,也应及时询问 [1]。 3. **由法务部审查决定**:报告后,潜在的利益冲突将由公司法务部进行审查并做出决定 [1]。此外,若您本人是董事或高管,涉及利益冲突的行为还须提前获得审计委员会书面同意 [1]。 **建议**:在您配偶实际开展筹备或经营之前,先按上述流程向公司如实报告情况,由公司审查认定。如未经报告擅自进行,可能违反公司制度;同时也要注意不得向配偶泄露公司的经营信息、业务数据等保密资料。 | P41: 员工道德规范准则.pdf:L17｜## 3. 利益冲突原则\n50477ce8-acfb-40a9-a8ad-c6ae467fa3ad 员工道德规范准则.pdf:19: 3.1.不得接受竞争对 | Q41: http://192.168.151.14:3000/c/0e37e646-dd4b-4c82-be2f-55d4a5259bcb | R41: 是 | S41: 无明显异常 | T41: 5 | U41: 5 | V41: 5 | W41: 否 | X41: 否 | Y41: 通过
A42: L1-0035 | B42: RUN-L1-008 | C42: 2026-08-20 | D42: 测试人员A | E42: =IFERROR(VLOOKUP(B42,'90-测试批次配置'!$A$4:$P$200,10,FALSE),"") | F42: PDF/DOCX | G42: 员工道德规范准则.pdf | H42: ≤2MB | I42: 同义改写 | J42: 中 | K42: 我把公司群里发的内部文件截了个图发朋友圈,应该没事吧? | L42: 是 | M42: 有事。4.1条规定未经公司授权或批准,不准对外提供标有密级的公司文件以及其它未经公开的经营状况、业务数据等资料、信息。5.2条还规定未经公司信息披露主管部门许可,不得擅自对外公开披露尚未公开的公司信息。 | N42: 员工道德规范准则.pdf /4.1 / 5.2 | O42: **这事有风险,建议尽快处理。** 根据《员工道德规范准则》的保密义务条款: - **第4.2条**:不得泄露与业务或职务有关的信息、资料、成果。凡涉及公司的,未经上级领导批准,不得对外公布。 - **第4.3条**:对通过职务行为或其他渠道获悉的公司/客户保密信息,有保密义务。 - **第4.4条**:对非职权范围内的机密,不打听、不猜测、不参与传播。 公司群里发的内部文件,属于与公司业务相关的内部信息,发到朋友圈就是"对外公布",即使你主观觉得"没什么敏感内容",未经批准就公开已经不符合规范要求。 **建议立即采取:** 1. ⏰ **马上删除**该朋友圈(越早越好,减少传播范围) 2. 📞 如已有同事/领导看到,主动向直属领导说明情况并道歉 3. 🔍 检查截图内容是否含客户信息、经营数据、未公开决策等敏感信息——如果涉及,需如实向上级报告 **以后注意**:想分享任何与公司相关的内容前,先问一句"是否经过批准可以对外公布?"拿不准就先别发,或先咨询上级/合规部门。 | P42: 反商业贿赂制度V1.0.pdf:L10｜2.2 适用于公司所有业务活动,涵盖但不限于国内与国际范围。包括公司内部各部门、子公司、合资企业、国内外采购与销售、项目合作,以及与国内外客户、供应商、代理商的 | Q42: http://192.168.151.14:3000/c/590672f9-33b7-4709-a544-4506dc138ff9 | R42: 是 | S42: 引用命中文档与期望不符 | T42: 4 | U42: 5 | V42: 4 | W42: 否 | X42: 否 | Y42: 通过 | AB42: 引用命中：['反商业贿赂制度V1.0.pdf']，期望来源：员工道德规范准则.pdf，疑似知识库内容重叠或检索偏差，建议人工核查
...

Sheet 92-文档解析Case
A1: Parse Case ID | B1: Run ID | C1: 执行日期 | D1: 执行测试人员 | E1: 知识库(同 90) | F1: 文档类型 | G1: 文档名称/组合 | H1: 文件大小(MB) | I1: 文件大小档位 | J1: 页数/Sheet数 | K1: 结构类型 | L1: 复杂度 | M1: 测试性质 | N1: 是否允许重复向量化 | O1: 预期结构/关键内容 | P1: 实际解析结果摘要 | Q1: 标题层级(0-5) | R1: 正文完整性(0-5) | S1: 表格结构(0-5) | T1: 代码/公式保真(0-5) | U1: 图片/OCR(0-5) | V1: 顺序正确性(0-5) | W1: 来源定位信息(0-5) | X1: 关键内容可检索 | Y1: 最终结果 | Z1: 解析问题类型 | AA1: 备注
A2: EX-PARSE-001 | B2: RUN-L1-004 | D2: 测试人员A | E2: =IFERROR(VLOOKUP(B2,'90-测试批次配置'!$A$4:$P$200,10,FALSE),"") | F2: Markdown | G2: VPN申请说明.md | H2: 0.3 | I2: ≤2MB | J2: 1 | K2: H1/H2标题+列表+代码块 | L2: 中等 | M2: 常规功能 | N2: 是 | O2: 标题层级正确；申请步骤完整；代码/命令块保持原样；关键字段可检索。 | P2: 标题、正文、列表和代码块均正常解析，关键步骤可检索。 | Q2: 5 | R2: 5 | S2: N/A | T2: 5 | U2: N/A | V2: 5 | W2: 5 | X2: 是 | Y2: 通过 | Z2: 无 | AA2: 示例：Markdown 正常解析。无表格/图片的指标填 N/A。
A3: EX-PARSE-002 | B3: RUN-L1-001 | D3: 测试人员B | E3: =IFERROR(VLOOKUP(B3,'90-测试批次配置'!$A$4:$P$200,10,FALSE),"") | F3: PDF | G3: 差旅管理制度.pdf | H3: 1.8 | I3: ≤2MB | J3: 18 | K3: 多页+表格+页眉页脚 | L3: 困难 | M3: 解析专项 | N3: 是 | O3: 正文阅读顺序正确；表格行列关系完整；重复页眉页脚不污染检索。 | P3: 正文正常，但住宿标准表格的城市级别和金额发生错位。 | Q3: 5 | R3: 5 | S3: 2 | T3: N/A | U3: N/A | V3: 5 | W3: 4 | X3: 部分 | Y3: 失败 | Z3: 表格错乱 | AA3: 示例：原始 PDF 有正确表格，但解析后行列关系错乱，应记录为解析问题。
A4: EX-PARSE-003 | B4: RUN-L1-003 | D4: 测试人员C | E4: =IFERROR(VLOOKUP(B4,'90-测试批次配置'!$A$4:$P$200,10,FALSE),"") | F4: Excel | G4: 审批矩阵.xlsx | H4: 1.2 | I4: ≤2MB | J4: 4 | K4: 多Sheet+合并单元格+公式 | L4: 困难 | M4: 解析专项 | N4: 是 | O4: Sheet 名可区分；角色、审批级别与数值保持对应；公式结果可读取。 | P4: 4 个 Sheet 均能区分，审批条件和角色关系完整，公式结果可检索。 | Q4: N/A | R4: 5 | S4: 5 | T4: 5 | U4: N/A | V4: 5 | W4: 5 | X4: 是 | Y4: 通过 | Z4: 无 | AA4: 示例：Excel 的标题层级和图片项可填 N/A，重点看表格、公式和 Sheet 语义。
A5: EX-PARSE-004 | B5: RUN-L1-002 | D5: 测试人员A | E5: =IFERROR(VLOOKUP(B5,'90-测试批次配置'!$A$4:$P$200,10,FALSE),"") | F5: Word | G5: 员工手册.docx | H5: 2.4 | I5: 2-10MB | J5: 35 | K5: 目录+标题+正文+表格 | L5: 中等 | M5: 解析专项 | N5: 尽量避免 | O5: 目录不应重复污染正文；标题层级正确；正文和表格顺序正常。 | P5: 正文完整，但目录内容被当作正文重复切分，检索时同一标题多次出现。 | Q5: 4 | R5: 2 | S5: 5 | T5: N/A | U5: N/A | V5: 4 | W5: 4 | X5: 部分 | Y5: 失败 | Z5: 其他 | AA5: 示例：目录被重复当正文入库，造成内容污染并影响检索；正文完整性按2分处理，因此最终判失败。
A6: EX-PARSE-005 | B6: RUN-L1-004 | D6: 测试人员B | E6: =IFERROR(VLOOKUP(B6,'90-测试批次配置'!$A$4:$P$200,10,FALSE),"") | F6: 图片 | G6: VPN流程图.png | H6: 0.8 | I6: ≤2MB | J6: 1 | K6: 流程图+中文文字+箭头 | L6: 困难 | M6: 解析专项 | N6: 是 | O6: OCR 正确识别关键节点；流程顺序和节点关系可用于问答。 | P6: 大部分文字可识别，但“部门负责人审批”被识别成“部门负贵人审批”，且箭头关系无法恢复。 | Q6: N/A | R6: 3 | S6: N/A | T6: N/A | U6: 2 | V6: 2 | W6: 3 | X6: 部分 | Y6: 失败 | Z6: OCR错误 | AA6: 示例：图片不仅看 OCR 字符，还要关注流程关系是否保留。
A7: EX-PARSE-006 | B7: RUN-L1-003 | D7: 测试人员C | E7: =IFERROR(VLOOKUP(B7,'90-测试批次配置'!$A$4:$P$200,10,FALSE),"") | F7: 混合 | G7: 员工手册.pdf + 请假FAQ.md + 审批矩阵.xlsx | H7: 4 | I7: 混合大小 | K7: PDF+Markdown+Excel 跨格式同主题 | L7: 困难 | M7: 混合文档专项 | N7: 尽量避免 | O7: 三个来源均可独立检索；同主题信息不互相覆盖；最终引用能区分来源。 | P7: 三个文件均成功解析并可独立召回；跨文档问题能同时引用 PDF 与 Excel，FAQ 可作为补充来源。 | Q7: 5 | R7: 5 | S7: 5 | T7: 5 | U7: N/A | V7: 5 | W7: 5 | X7: 是 | Y7: 通过 | Z7: 无 | AA7: 示例：混合类型重点看跨格式召回、来源区分和引用准确性。
E8: =IFERROR(VLOOKUP(B8,'90-测试批次配置'!$A$4:$P$200,10,FALSE),"")
E9: =IFERROR(VLOOKUP(B9,'90-测试批次配置'!$A$4:$P$200,10,FALSE),"")
E10: =IFERROR(VLOOKUP(B10,'90-测试批次配置'!$A$4:$P$200,10,FALSE),"")
E11: =IFERROR(VLOOKUP(B11,'90-测试批次配置'!$A$4:$P$200,10,FALSE),"")
E12: =IFERROR(VLOOKUP(B12,'90-测试批次配置'!$A$4:$P$200,10,FALSE),"")
E13: =IFERROR(VLOOKUP(B13,'90-测试批次配置'!$A$4:$P$200,10,FALSE),"")
E14: =IFERROR(VLOOKUP(B14,'90-测试批次配置'!$A$4:$P$200,10,FALSE),"")
E15: =IFERROR(VLOOKUP(B15,'90-测试批次配置'!$A$4:$P$200,10,FALSE),"")
E16: =IFERROR(VLOOKUP(B16,'90-测试批次配置'!$A$4:$P$200,10,FALSE),"")
E17: =IFERROR(VLOOKUP(B17,'90-测试批次配置'!$A$4:$P$200,10,FALSE),"")
E18: =IFERROR(VLOOKUP(B18,'90-测试批次配置'!$A$4:$P$200,10,FALSE),"")
E19: =IFERROR(VLOOKUP(B19,'90-测试批次配置'!$A$4:$P$200,10,FALSE),"")
... E200: =IFERROR(VLOOKUP(B200,'90-测试批次配置'!$A$4:$P$200,10,FALSE),"")
